2025-10-10 03:52:21.941 | ERROR    | app.ui.pages.dashboard_page:refresh_data:62 - No se pudo cargar dashboard: (mysql.connector.errors.ProgrammingError) 1045 (28000): Access denied for user 'matiasciafardini'@'188.81.239.217' (using password: NO)
(Background on this error at: https://sqlalche.me/e/20/f405)
Traceback (most recent call last):

  File "C:\Users\mat_i\AppData\Local\Programs\Python\Python313\Lib\site-packages\mysql\connector\connection_cext.py", line 354, in _open_connection
    self._cmysql.connect(**cnx_kwargs)
    │    │       │         └ {'host': '34.176.19.140', 'user': 'matiasciafardini', 'password': '', 'password1': '', 'password2': '', 'password3': '', 'dat...
    │    │       └ <method 'connect' of '_mysql_connector.MySQL' objects>
    │    └ <_mysql_connector.MySQL object at 0x0000019B94C985C0>
    └ <mysql.connector.connection_cext.CMySQLConnection object at 0x0000019B96EF8D70>

_mysql_connector.MySQLInterfaceError: Access denied for user 'matiasciafardini'@'188.81.239.217' (using password: NO)


The above exception was the direct cause of the following exception:


Traceback (most recent call last):

  File "C:\Users\mat_i\AppData\Local\Programs\Python\Python313\Lib\site-packages\sqlalchemy\engine\base.py", line 146, in __init__
    self._dbapi_connection = engine.raw_connection()
    │                        │      └ <function Engine.raw_connection at 0x0000019B955167A0>
    │                        └ Engine(mysql+mysqlconnector://matiasciafardini:***@34.176.19.140:3306/motoagency?charset=utf8mb4)
    └ <sqlalchemy.engine.base.Connection object at 0x0000019B96EF8C20>
  File "C:\Users\mat_i\AppData\Local\Programs\Python\Python313\Lib\site-packages\sqlalchemy\engine\base.py", line 3302, in raw_connection
    return self.pool.connect()
           │    │    └ <function Pool.connect at 0x0000019B950AB6A0>
           │    └ <sqlalchemy.pool.impl.QueuePool object at 0x0000019B96EF82F0>
           └ Engine(mysql+mysqlconnector://matiasciafardini:***@34.176.19.140:3306/motoagency?charset=utf8mb4)
  File "C:\Users\mat_i\AppData\Local\Programs\Python\Python313\Lib\site-packages\sqlalchemy\pool\base.py", line 449, in connect
    return _ConnectionFairy._checkout(self)
           │                │         └ <sqlalchemy.pool.impl.QueuePool object at 0x0000019B96EF82F0>
           │                └ <classmethod(<function _ConnectionFairy._checkout at 0x0000019B950E5800>)>
           └ <class 'sqlalchemy.pool.base._ConnectionFairy'>
  File "C:\Users\mat_i\AppData\Local\Programs\Python\Python313\Lib\site-packages\sqlalchemy\pool\base.py", line 1263, in _checkout
    fairy = _ConnectionRecord.checkout(pool)
            │                 │        └ <sqlalchemy.pool.impl.QueuePool object at 0x0000019B96EF82F0>
            │                 └ <classmethod(<function _ConnectionRecord.checkout at 0x0000019B950E4360>)>
            └ <class 'sqlalchemy.pool.base._ConnectionRecord'>
  File "C:\Users\mat_i\AppData\Local\Programs\Python\Python313\Lib\site-packages\sqlalchemy\pool\base.py", line 712, in checkout
    rec = pool._do_get()
          │    └ <function QueuePool._do_get at 0x0000019B950E7600>
          └ <sqlalchemy.pool.impl.QueuePool object at 0x0000019B96EF82F0>
  File "C:\Users\mat_i\AppData\Local\Programs\Python\Python313\Lib\site-packages\sqlalchemy\pool\impl.py", line 179, in _do_get
    with util.safe_reraise():
         │    └ <class 'sqlalchemy.util.langhelpers.safe_reraise'>
         └ <module 'sqlalchemy.util' from 'C:\\Users\\mat_i\\AppData\\Local\\Programs\\Python\\Python313\\Lib\\site-packages\\sqlalchemy...
  File "C:\Users\mat_i\AppData\Local\Programs\Python\Python313\Lib\site-packages\sqlalchemy\util\langhelpers.py", line 146, in __exit__
    raise exc_value.with_traceback(exc_tb)
          │         │              └ <traceback object at 0x0000019B96F21C00>
          │         └ <method 'with_traceback' of 'BaseException' objects>
          └ ProgrammingError(1045, "1045 (28000): Access denied for user 'matiasciafardini'@'188.81.239.217' (using password: NO)", '28000')
  File "C:\Users\mat_i\AppData\Local\Programs\Python\Python313\Lib\site-packages\sqlalchemy\pool\impl.py", line 177, in _do_get
    return self._create_connection()
           │    └ <function Pool._create_connection at 0x0000019B950AB420>
           └ <sqlalchemy.pool.impl.QueuePool object at 0x0000019B96EF82F0>
  File "C:\Users\mat_i\AppData\Local\Programs\Python\Python313\Lib\site-packages\sqlalchemy\pool\base.py", line 390, in _create_connection
    return _ConnectionRecord(self)
           │                 └ <sqlalchemy.pool.impl.QueuePool object at 0x0000019B96EF82F0>
           └ <class 'sqlalchemy.pool.base._ConnectionRecord'>
  File "C:\Users\mat_i\AppData\Local\Programs\Python\Python313\Lib\site-packages\sqlalchemy\pool\base.py", line 674, in __init__
    self.__connect()
    └ <sqlalchemy.pool.base._ConnectionRecord object at 0x0000019B91B96E70>
  File "C:\Users\mat_i\AppData\Local\Programs\Python\Python313\Lib\site-packages\sqlalchemy\pool\base.py", line 900, in __connect
    with util.safe_reraise():
         │    └ <class 'sqlalchemy.util.langhelpers.safe_reraise'>
         └ <module 'sqlalchemy.util' from 'C:\\Users\\mat_i\\AppData\\Local\\Programs\\Python\\Python313\\Lib\\site-packages\\sqlalchemy...
  File "C:\Users\mat_i\AppData\Local\Programs\Python\Python313\Lib\site-packages\sqlalchemy\util\langhelpers.py", line 146, in __exit__
    raise exc_value.with_traceback(exc_tb)
          │         │              └ <traceback object at 0x0000019B96F21480>
          │         └ <method 'with_traceback' of 'BaseException' objects>
          └ ProgrammingError(1045, "1045 (28000): Access denied for user 'matiasciafardini'@'188.81.239.217' (using password: NO)", '28000')
  File "C:\Users\mat_i\AppData\Local\Programs\Python\Python313\Lib\site-packages\sqlalchemy\pool\base.py", line 896, in __connect
    self.dbapi_connection = connection = pool._invoke_creator(self)
    │    │                               │    │               └ <sqlalchemy.pool.base._ConnectionRecord object at 0x0000019B91B96E70>
    │    │                               │    └ <function create_engine.<locals>.connect at 0x0000019B959B07C0>
    │    │                               └ <sqlalchemy.pool.impl.QueuePool object at 0x0000019B96EF82F0>
    │    └ <member 'dbapi_connection' of '_ConnectionRecord' objects>
    └ <sqlalchemy.pool.base._ConnectionRecord object at 0x0000019B91B96E70>
  File "C:\Users\mat_i\AppData\Local\Programs\Python\Python313\Lib\site-packages\sqlalchemy\engine\create.py", line 643, in connect
    return dialect.connect(*cargs, **cparams)
           │       │        │        └ {'host': '34.176.19.140', 'database': 'motoagency', 'user': 'matiasciafardini', 'port': 3306, 'charset': 'utf8mb4', 'buffered...
           │       │        └ []
           │       └ <function DefaultDialect.connect at 0x0000019B95619C60>
           └ <sqlalchemy.dialects.mysql.mysqlconnector.MySQLDialect_mysqlconnector object at 0x0000019B959E7E00>
  File "C:\Users\mat_i\AppData\Local\Programs\Python\Python313\Lib\site-packages\sqlalchemy\engine\default.py", line 621, in connect
    return self.loaded_dbapi.connect(*cargs, **cparams)
           │    │            │        │        └ {'host': '34.176.19.140', 'database': 'motoagency', 'user': 'matiasciafardini', 'port': 3306, 'charset': 'utf8mb4', 'buffered...
           │    │            │        └ ()
           │    │            └ <function connect at 0x0000019B96EEF4C0>
           │    └ <module 'mysql.connector' from 'C:\\Users\\mat_i\\AppData\\Local\\Programs\\Python\\Python313\\Lib\\site-packages\\mysql\\con...
           └ <sqlalchemy.dialects.mysql.mysqlconnector.MySQLDialect_mysqlconnector object at 0x0000019B959E7E00>
  File "C:\Users\mat_i\AppData\Local\Programs\Python\Python313\Lib\site-packages\mysql\connector\pooling.py", line 322, in connect
    return CMySQLConnection(*args, **kwargs)
           │                 │       └ {'host': '34.176.19.140', 'database': 'motoagency', 'user': 'matiasciafardini', 'port': 3306, 'charset': 'utf8mb4', 'buffered...
           │                 └ ()
           └ <class 'mysql.connector.connection_cext.CMySQLConnection'>
  File "C:\Users\mat_i\AppData\Local\Programs\Python\Python313\Lib\site-packages\mysql\connector\connection_cext.py", line 142, in __init__
    self.connect(**kwargs)
    │    │         └ {'host': '34.176.19.140', 'database': 'motoagency', 'user': 'matiasciafardini', 'port': 3306, 'charset': 'utf8mb4', 'buffered...
    │    └ <function MySQLConnectionAbstract.connect at 0x0000019B95B4B600>
    └ <mysql.connector.connection_cext.CMySQLConnection object at 0x0000019B96EF8D70>
  File "C:\Users\mat_i\AppData\Local\Programs\Python\Python313\Lib\site-packages\mysql\connector\abstracts.py", line 1604, in connect
    self._open_connection()
    │    └ <function CMySQLConnection._open_connection at 0x0000019B96ECB7E0>
    └ <mysql.connector.connection_cext.CMySQLConnection object at 0x0000019B96EF8D70>
  File "C:\Users\mat_i\AppData\Local\Programs\Python\Python313\Lib\site-packages\mysql\connector\connection_cext.py", line 360, in _open_connection
    raise get_mysql_exception(
          └ <function get_mysql_exception at 0x0000019B95AD07C0>

mysql.connector.errors.ProgrammingError: 1045 (28000): Access denied for user 'matiasciafardini'@'188.81.239.217' (using password: NO)


The above exception was the direct cause of the following exception:


Traceback (most recent call last):

  File "C:\Users\mat_i\OneDrive\Escritorio\App_gussoni\run.py", line 4, in <module>
    main()
    └ <function main at 0x0000019B94565760>

  File "C:\Users\mat_i\OneDrive\Escritorio\App_gussoni\app\ui\main.py", line 11, in main
    win = MainWindow()
          └ <class 'app.ui.main_window.MainWindow'>

  File "C:\Users\mat_i\OneDrive\Escritorio\App_gussoni\app\ui\main_window.py", line 25, in __init__
    self.pageDashboard = DashboardPage(self)
    │                    │             └ <app.ui.main_window.MainWindow(0x19b92686540, name="MainWindow") at 0x0000019B92C05A40>
    │                    └ <class 'app.ui.pages.dashboard_page.DashboardPage'>
    └ <app.ui.main_window.MainWindow(0x19b92686540, name="MainWindow") at 0x0000019B92C05A40>

  File "C:\Users\mat_i\OneDrive\Escritorio\App_gussoni\app\ui\pages\dashboard_page.py", line 53, in __init__
    self.refresh_data()
    │    └ <function DashboardPage.refresh_data at 0x0000019B96F0AE80>
    └ <app.ui.pages.dashboard_page.DashboardPage(0x19b94941320) at 0x0000019B96F03BC0>

> File "C:\Users\mat_i\OneDrive\Escritorio\App_gussoni\app\ui\pages\dashboard_page.py", line 60, in refresh_data
    data: DashboardData = service.load_dashboard()
                          │       └ <function DashboardService.load_dashboard at 0x0000019B9599B740>
                          └ <app.services.dashboard_service.DashboardService object at 0x0000019B944A67B0>

  File "C:\Users\mat_i\OneDrive\Escritorio\App_gussoni\app\services\dashboard_service.py", line 21, in load_dashboard
    ventas_mes = self.ventas_repo.metrics_mes_actual()
                 │    │           └ <function VentasRepository.metrics_mes_actual at 0x0000019B9599BC40>
                 │    └ <app.repositories.ventas_repository.VentasRepository object at 0x0000019B96EF8830>
                 └ <app.services.dashboard_service.DashboardService object at 0x0000019B944A67B0>

  File "C:\Users\mat_i\OneDrive\Escritorio\App_gussoni\app\repositories\ventas_repository.py", line 24, in metrics_mes_actual
    row = self.db.execute(q, {"ini": first, "fin": fin}).mappings().one()
          │    │  │       │          │             └ datetime.date(2025, 11, 1)
          │    │  │       │          └ datetime.date(2025, 10, 1)
          │    │  │       └ <sqlalchemy.sql.elements.TextClause object at 0x0000019B96EF8980>
          │    │  └ <function Session.execute at 0x0000019B958C7EC0>
          │    └ <sqlalchemy.orm.session.Session object at 0x0000019B944A6A50>
          └ <app.repositories.ventas_repository.VentasRepository object at 0x0000019B96EF8830>

  File "C:\Users\mat_i\AppData\Local\Programs\Python\Python313\Lib\site-packages\sqlalchemy\orm\session.py", line 2362, in execute
    return self._execute_internal(
           │    └ <function Session._execute_internal at 0x0000019B958C7BA0>
           └ <sqlalchemy.orm.session.Session object at 0x0000019B944A6A50>
  File "C:\Users\mat_i\AppData\Local\Programs\Python\Python313\Lib\site-packages\sqlalchemy\orm\session.py", line 2237, in _execute_internal
    conn = self._connection_for_bind(bind)
           │    │                    └ Engine(mysql+mysqlconnector://matiasciafardini:***@34.176.19.140:3306/motoagency?charset=utf8mb4)
           │    └ <function Session._connection_for_bind at 0x0000019B958C7920>
           └ <sqlalchemy.orm.session.Session object at 0x0000019B944A6A50>
  File "C:\Users\mat_i\AppData\Local\Programs\Python\Python313\Lib\site-packages\sqlalchemy\orm\session.py", line 2106, in _connection_for_bind
    return trans._connection_for_bind(engine, execution_options)
           │     │                    │       └ None
           │     │                    └ Engine(mysql+mysqlconnector://matiasciafardini:***@34.176.19.140:3306/motoagency?charset=utf8mb4)
           │     └ <function SessionTransaction._connection_for_bind at 0x0000019B958C62A0>
           └ <sqlalchemy.orm.session.SessionTransaction object at 0x0000019B9568EE10>
  File "<string>", line 2, in _connection_for_bind
  File "C:\Users\mat_i\AppData\Local\Programs\Python\Python313\Lib\site-packages\sqlalchemy\orm\state_changes.py", line 139, in _go
    ret_value = fn(self, *arg, **kw)
                │  │      │      └ {}
                │  │      └ (Engine(mysql+mysqlconnector://matiasciafardini:***@34.176.19.140:3306/motoagency?charset=utf8mb4), None)
                │  └ <sqlalchemy.orm.session.SessionTransaction object at 0x0000019B9568EE10>
                └ <function SessionTransaction._connection_for_bind at 0x0000019B958C6200>
  File "C:\Users\mat_i\AppData\Local\Programs\Python\Python313\Lib\site-packages\sqlalchemy\orm\session.py", line 1189, in _connection_for_bind
    conn = bind.connect()
           │    └ <function Engine.connect at 0x0000019B95516700>
           └ Engine(mysql+mysqlconnector://matiasciafardini:***@34.176.19.140:3306/motoagency?charset=utf8mb4)
  File "C:\Users\mat_i\AppData\Local\Programs\Python\Python313\Lib\site-packages\sqlalchemy\engine\base.py", line 3278, in connect
    return self._connection_cls(self)
           │    │               └ Engine(mysql+mysqlconnector://matiasciafardini:***@34.176.19.140:3306/motoagency?charset=utf8mb4)
           │    └ <class 'sqlalchemy.engine.base.Connection'>
           └ Engine(mysql+mysqlconnector://matiasciafardini:***@34.176.19.140:3306/motoagency?charset=utf8mb4)
  File "C:\Users\mat_i\AppData\Local\Programs\Python\Python313\Lib\site-packages\sqlalchemy\engine\base.py", line 148, in __init__
    Connection._handle_dbapi_exception_noconnection(
    │          └ <classmethod(<function Connection._handle_dbapi_exception_noconnection at 0x0000019B95513F60>)>
    └ <class 'sqlalchemy.engine.base.Connection'>
  File "C:\Users\mat_i\AppData\Local\Programs\Python\Python313\Lib\site-packages\sqlalchemy\engine\base.py", line 2442, in _handle_dbapi_exception_noconnection
    raise sqlalchemy_exception.with_traceback(exc_info[2]) from e
          │                    │              │                 └ ProgrammingError(1045, "1045 (28000): Access denied for user 'matiasciafardini'@'188.81.239.217' (using password: NO)", '28000')
          │                    │              └ (<class 'mysql.connector.errors.ProgrammingError'>, ProgrammingError(1045, "1045 (28000): Access denied for user 'matiasciafa...
          │                    └ <method 'with_traceback' of 'BaseException' objects>
          └ ProgrammingError("(mysql.connector.errors.ProgrammingError) 1045 (28000): Access denied for user 'matiasciafardini'@'188.81.2...
  File "C:\Users\mat_i\AppData\Local\Programs\Python\Python313\Lib\site-packages\sqlalchemy\engine\base.py", line 146, in __init__
    self._dbapi_connection = engine.raw_connection()
    │                        │      └ <function Engine.raw_connection at 0x0000019B955167A0>
    │                        └ Engine(mysql+mysqlconnector://matiasciafardini:***@34.176.19.140:3306/motoagency?charset=utf8mb4)
    └ <sqlalchemy.engine.base.Connection object at 0x0000019B96EF8C20>
  File "C:\Users\mat_i\AppData\Local\Programs\Python\Python313\Lib\site-packages\sqlalchemy\engine\base.py", line 3302, in raw_connection
    return self.pool.connect()
           │    │    └ <function Pool.connect at 0x0000019B950AB6A0>
           │    └ <sqlalchemy.pool.impl.QueuePool object at 0x0000019B96EF82F0>
           └ Engine(mysql+mysqlconnector://matiasciafardini:***@34.176.19.140:3306/motoagency?charset=utf8mb4)
  File "C:\Users\mat_i\AppData\Local\Programs\Python\Python313\Lib\site-packages\sqlalchemy\pool\base.py", line 449, in connect
    return _ConnectionFairy._checkout(self)
           │                │         └ <sqlalchemy.pool.impl.QueuePool object at 0x0000019B96EF82F0>
           │                └ <classmethod(<function _ConnectionFairy._checkout at 0x0000019B950E5800>)>
           └ <class 'sqlalchemy.pool.base._ConnectionFairy'>
  File "C:\Users\mat_i\AppData\Local\Programs\Python\Python313\Lib\site-packages\sqlalchemy\pool\base.py", line 1263, in _checkout
    fairy = _ConnectionRecord.checkout(pool)
            │                 │        └ <sqlalchemy.pool.impl.QueuePool object at 0x0000019B96EF82F0>
            │                 └ <classmethod(<function _ConnectionRecord.checkout at 0x0000019B950E4360>)>
            └ <class 'sqlalchemy.pool.base._ConnectionRecord'>
  File "C:\Users\mat_i\AppData\Local\Programs\Python\Python313\Lib\site-packages\sqlalchemy\pool\base.py", line 712, in checkout
    rec = pool._do_get()
          │    └ <function QueuePool._do_get at 0x0000019B950E7600>
          └ <sqlalchemy.pool.impl.QueuePool object at 0x0000019B96EF82F0>
  File "C:\Users\mat_i\AppData\Local\Programs\Python\Python313\Lib\site-packages\sqlalchemy\pool\impl.py", line 179, in _do_get
    with util.safe_reraise():
         │    └ <class 'sqlalchemy.util.langhelpers.safe_reraise'>
         └ <module 'sqlalchemy.util' from 'C:\\Users\\mat_i\\AppData\\Local\\Programs\\Python\\Python313\\Lib\\site-packages\\sqlalchemy...
  File "C:\Users\mat_i\AppData\Local\Programs\Python\Python313\Lib\site-packages\sqlalchemy\util\langhelpers.py", line 146, in __exit__
    raise exc_value.with_traceback(exc_tb)
          │         │              └ <traceback object at 0x0000019B96F21C00>
          │         └ <method 'with_traceback' of 'BaseException' objects>
          └ ProgrammingError(1045, "1045 (28000): Access denied for user 'matiasciafardini'@'188.81.239.217' (using password: NO)", '28000')
  File "C:\Users\mat_i\AppData\Local\Programs\Python\Python313\Lib\site-packages\sqlalchemy\pool\impl.py", line 177, in _do_get
    return self._create_connection()
           │    └ <function Pool._create_connection at 0x0000019B950AB420>
           └ <sqlalchemy.pool.impl.QueuePool object at 0x0000019B96EF82F0>
  File "C:\Users\mat_i\AppData\Local\Programs\Python\Python313\Lib\site-packages\sqlalchemy\pool\base.py", line 390, in _create_connection
    return _ConnectionRecord(self)
           │                 └ <sqlalchemy.pool.impl.QueuePool object at 0x0000019B96EF82F0>
           └ <class 'sqlalchemy.pool.base._ConnectionRecord'>
  File "C:\Users\mat_i\AppData\Local\Programs\Python\Python313\Lib\site-packages\sqlalchemy\pool\base.py", line 674, in __init__
    self.__connect()
    └ <sqlalchemy.pool.base._ConnectionRecord object at 0x0000019B91B96E70>
  File "C:\Users\mat_i\AppData\Local\Programs\Python\Python313\Lib\site-packages\sqlalchemy\pool\base.py", line 900, in __connect
    with util.safe_reraise():
         │    └ <class 'sqlalchemy.util.langhelpers.safe_reraise'>
         └ <module 'sqlalchemy.util' from 'C:\\Users\\mat_i\\AppData\\Local\\Programs\\Python\\Python313\\Lib\\site-packages\\sqlalchemy...
  File "C:\Users\mat_i\AppData\Local\Programs\Python\Python313\Lib\site-packages\sqlalchemy\util\langhelpers.py", line 146, in __exit__
    raise exc_value.with_traceback(exc_tb)
          │         │              └ <traceback object at 0x0000019B96F21480>
          │         └ <method 'with_traceback' of 'BaseException' objects>
          └ ProgrammingError(1045, "1045 (28000): Access denied for user 'matiasciafardini'@'188.81.239.217' (using password: NO)", '28000')
  File "C:\Users\mat_i\AppData\Local\Programs\Python\Python313\Lib\site-packages\sqlalchemy\pool\base.py", line 896, in __connect
    self.dbapi_connection = connection = pool._invoke_creator(self)
    │    │                               │    │               └ <sqlalchemy.pool.base._ConnectionRecord object at 0x0000019B91B96E70>
    │    │                               │    └ <function create_engine.<locals>.connect at 0x0000019B959B07C0>
    │    │                               └ <sqlalchemy.pool.impl.QueuePool object at 0x0000019B96EF82F0>
    │    └ <member 'dbapi_connection' of '_ConnectionRecord' objects>
    └ <sqlalchemy.pool.base._ConnectionRecord object at 0x0000019B91B96E70>
  File "C:\Users\mat_i\AppData\Local\Programs\Python\Python313\Lib\site-packages\sqlalchemy\engine\create.py", line 643, in connect
    return dialect.connect(*cargs, **cparams)
           │       │        │        └ {'host': '34.176.19.140', 'database': 'motoagency', 'user': 'matiasciafardini', 'port': 3306, 'charset': 'utf8mb4', 'buffered...
           │       │        └ []
           │       └ <function DefaultDialect.connect at 0x0000019B95619C60>
           └ <sqlalchemy.dialects.mysql.mysqlconnector.MySQLDialect_mysqlconnector object at 0x0000019B959E7E00>
  File "C:\Users\mat_i\AppData\Local\Programs\Python\Python313\Lib\site-packages\sqlalchemy\engine\default.py", line 621, in connect
    return self.loaded_dbapi.connect(*cargs, **cparams)
           │    │            │        │        └ {'host': '34.176.19.140', 'database': 'motoagency', 'user': 'matiasciafardini', 'port': 3306, 'charset': 'utf8mb4', 'buffered...
           │    │            │        └ ()
           │    │            └ <function connect at 0x0000019B96EEF4C0>
           │    └ <module 'mysql.connector' from 'C:\\Users\\mat_i\\AppData\\Local\\Programs\\Python\\Python313\\Lib\\site-packages\\mysql\\con...
           └ <sqlalchemy.dialects.mysql.mysqlconnector.MySQLDialect_mysqlconnector object at 0x0000019B959E7E00>
  File "C:\Users\mat_i\AppData\Local\Programs\Python\Python313\Lib\site-packages\mysql\connector\pooling.py", line 322, in connect
    return CMySQLConnection(*args, **kwargs)
           │                 │       └ {'host': '34.176.19.140', 'database': 'motoagency', 'user': 'matiasciafardini', 'port': 3306, 'charset': 'utf8mb4', 'buffered...
           │                 └ ()
           └ <class 'mysql.connector.connection_cext.CMySQLConnection'>
  File "C:\Users\mat_i\AppData\Local\Programs\Python\Python313\Lib\site-packages\mysql\connector\connection_cext.py", line 142, in __init__
    self.connect(**kwargs)
    │    │         └ {'host': '34.176.19.140', 'database': 'motoagency', 'user': 'matiasciafardini', 'port': 3306, 'charset': 'utf8mb4', 'buffered...
    │    └ <function MySQLConnectionAbstract.connect at 0x0000019B95B4B600>
    └ <mysql.connector.connection_cext.CMySQLConnection object at 0x0000019B96EF8D70>
  File "C:\Users\mat_i\AppData\Local\Programs\Python\Python313\Lib\site-packages\mysql\connector\abstracts.py", line 1604, in connect
    self._open_connection()
    │    └ <function CMySQLConnection._open_connection at 0x0000019B96ECB7E0>
    └ <mysql.connector.connection_cext.CMySQLConnection object at 0x0000019B96EF8D70>
  File "C:\Users\mat_i\AppData\Local\Programs\Python\Python313\Lib\site-packages\mysql\connector\connection_cext.py", line 360, in _open_connection
    raise get_mysql_exception(
          └ <function get_mysql_exception at 0x0000019B95AD07C0>

sqlalchemy.exc.ProgrammingError: (mysql.connector.errors.ProgrammingError) 1045 (28000): Access denied for user 'matiasciafardini'@'188.81.239.217' (using password: NO)
(Background on this error at: https://sqlalche.me/e/20/f405)
2025-10-10 03:53:54.458 | ERROR    | app.ui.pages.dashboard_page:refresh_data:71 - No se pudo cargar dashboard: (mysql.connector.errors.ProgrammingError) 1045 (28000): Access denied for user 'matiasciafardini'@'188.81.239.217' (using password: NO)
(Background on this error at: https://sqlalche.me/e/20/f405)
Traceback (most recent call last):

  File "C:\Users\mat_i\AppData\Local\Programs\Python\Python313\Lib\site-packages\mysql\connector\connection_cext.py", line 354, in _open_connection
    self._cmysql.connect(**cnx_kwargs)
    │    │       │         └ {'host': '34.176.19.140', 'user': 'matiasciafardini', 'password': '', 'password1': '', 'password2': '', 'password3': '', 'dat...
    │    │       └ <method 'connect' of '_mysql_connector.MySQL' objects>
    │    └ <_mysql_connector.MySQL object at 0x000001C8B518B6E0>
    └ <mysql.connector.connection_cext.CMySQLConnection object at 0x000001C8B7345010>

_mysql_connector.MySQLInterfaceError: Access denied for user 'matiasciafardini'@'188.81.239.217' (using password: NO)


The above exception was the direct cause of the following exception:


Traceback (most recent call last):

  File "C:\Users\mat_i\AppData\Local\Programs\Python\Python313\Lib\site-packages\sqlalchemy\engine\base.py", line 146, in __init__
    self._dbapi_connection = engine.raw_connection()
    │                        │      └ <function Engine.raw_connection at 0x000001C8B595EAC0>
    │                        └ Engine(mysql+mysqlconnector://matiasciafardini:***@34.176.19.140:3306/motoagency?charset=utf8mb4)
    └ <sqlalchemy.engine.base.Connection object at 0x000001C8B7344EC0>
  File "C:\Users\mat_i\AppData\Local\Programs\Python\Python313\Lib\site-packages\sqlalchemy\engine\base.py", line 3302, in raw_connection
    return self.pool.connect()
           │    │    └ <function Pool.connect at 0x000001C8B54F39C0>
           │    └ <sqlalchemy.pool.impl.QueuePool object at 0x000001C8B7344590>
           └ Engine(mysql+mysqlconnector://matiasciafardini:***@34.176.19.140:3306/motoagency?charset=utf8mb4)
  File "C:\Users\mat_i\AppData\Local\Programs\Python\Python313\Lib\site-packages\sqlalchemy\pool\base.py", line 449, in connect
    return _ConnectionFairy._checkout(self)
           │                │         └ <sqlalchemy.pool.impl.QueuePool object at 0x000001C8B7344590>
           │                └ <classmethod(<function _ConnectionFairy._checkout at 0x000001C8B5525B20>)>
           └ <class 'sqlalchemy.pool.base._ConnectionFairy'>
  File "C:\Users\mat_i\AppData\Local\Programs\Python\Python313\Lib\site-packages\sqlalchemy\pool\base.py", line 1263, in _checkout
    fairy = _ConnectionRecord.checkout(pool)
            │                 │        └ <sqlalchemy.pool.impl.QueuePool object at 0x000001C8B7344590>
            │                 └ <classmethod(<function _ConnectionRecord.checkout at 0x000001C8B5524680>)>
            └ <class 'sqlalchemy.pool.base._ConnectionRecord'>
  File "C:\Users\mat_i\AppData\Local\Programs\Python\Python313\Lib\site-packages\sqlalchemy\pool\base.py", line 712, in checkout
    rec = pool._do_get()
          │    └ <function QueuePool._do_get at 0x000001C8B5527920>
          └ <sqlalchemy.pool.impl.QueuePool object at 0x000001C8B7344590>
  File "C:\Users\mat_i\AppData\Local\Programs\Python\Python313\Lib\site-packages\sqlalchemy\pool\impl.py", line 179, in _do_get
    with util.safe_reraise():
         │    └ <class 'sqlalchemy.util.langhelpers.safe_reraise'>
         └ <module 'sqlalchemy.util' from 'C:\\Users\\mat_i\\AppData\\Local\\Programs\\Python\\Python313\\Lib\\site-packages\\sqlalchemy...
  File "C:\Users\mat_i\AppData\Local\Programs\Python\Python313\Lib\site-packages\sqlalchemy\util\langhelpers.py", line 146, in __exit__
    raise exc_value.with_traceback(exc_tb)
          │         │              └ <traceback object at 0x000001C8B734E880>
          │         └ <method 'with_traceback' of 'BaseException' objects>
          └ ProgrammingError(1045, "1045 (28000): Access denied for user 'matiasciafardini'@'188.81.239.217' (using password: NO)", '28000')
  File "C:\Users\mat_i\AppData\Local\Programs\Python\Python313\Lib\site-packages\sqlalchemy\pool\impl.py", line 177, in _do_get
    return self._create_connection()
           │    └ <function Pool._create_connection at 0x000001C8B54F3740>
           └ <sqlalchemy.pool.impl.QueuePool object at 0x000001C8B7344590>
  File "C:\Users\mat_i\AppData\Local\Programs\Python\Python313\Lib\site-packages\sqlalchemy\pool\base.py", line 390, in _create_connection
    return _ConnectionRecord(self)
           │                 └ <sqlalchemy.pool.impl.QueuePool object at 0x000001C8B7344590>
           └ <class 'sqlalchemy.pool.base._ConnectionRecord'>
  File "C:\Users\mat_i\AppData\Local\Programs\Python\Python313\Lib\site-packages\sqlalchemy\pool\base.py", line 674, in __init__
    self.__connect()
    └ <sqlalchemy.pool.base._ConnectionRecord object at 0x000001C8B1FA6E70>
  File "C:\Users\mat_i\AppData\Local\Programs\Python\Python313\Lib\site-packages\sqlalchemy\pool\base.py", line 900, in __connect
    with util.safe_reraise():
         │    └ <class 'sqlalchemy.util.langhelpers.safe_reraise'>
         └ <module 'sqlalchemy.util' from 'C:\\Users\\mat_i\\AppData\\Local\\Programs\\Python\\Python313\\Lib\\site-packages\\sqlalchemy...
  File "C:\Users\mat_i\AppData\Local\Programs\Python\Python313\Lib\site-packages\sqlalchemy\util\langhelpers.py", line 146, in __exit__
    raise exc_value.with_traceback(exc_tb)
          │         │              └ <traceback object at 0x000001C8B734E380>
          │         └ <method 'with_traceback' of 'BaseException' objects>
          └ ProgrammingError(1045, "1045 (28000): Access denied for user 'matiasciafardini'@'188.81.239.217' (using password: NO)", '28000')
  File "C:\Users\mat_i\AppData\Local\Programs\Python\Python313\Lib\site-packages\sqlalchemy\pool\base.py", line 896, in __connect
    self.dbapi_connection = connection = pool._invoke_creator(self)
    │    │                               │    │               └ <sqlalchemy.pool.base._ConnectionRecord object at 0x000001C8B1FA6E70>
    │    │                               │    └ <function create_engine.<locals>.connect at 0x000001C8B5DFCAE0>
    │    │                               └ <sqlalchemy.pool.impl.QueuePool object at 0x000001C8B7344590>
    │    └ <member 'dbapi_connection' of '_ConnectionRecord' objects>
    └ <sqlalchemy.pool.base._ConnectionRecord object at 0x000001C8B1FA6E70>
  File "C:\Users\mat_i\AppData\Local\Programs\Python\Python313\Lib\site-packages\sqlalchemy\engine\create.py", line 643, in connect
    return dialect.connect(*cargs, **cparams)
           │       │        │        └ {'host': '34.176.19.140', 'database': 'motoagency', 'user': 'matiasciafardini', 'port': 3306, 'charset': 'utf8mb4', 'buffered...
           │       │        └ []
           │       └ <function DefaultDialect.connect at 0x000001C8B5A4DF80>
           └ <sqlalchemy.dialects.mysql.mysqlconnector.MySQLDialect_mysqlconnector object at 0x000001C8B5E2BCB0>
  File "C:\Users\mat_i\AppData\Local\Programs\Python\Python313\Lib\site-packages\sqlalchemy\engine\default.py", line 621, in connect
    return self.loaded_dbapi.connect(*cargs, **cparams)
           │    │            │        │        └ {'host': '34.176.19.140', 'database': 'motoagency', 'user': 'matiasciafardini', 'port': 3306, 'charset': 'utf8mb4', 'buffered...
           │    │            │        └ ()
           │    │            └ <function connect at 0x000001C8B7340040>
           │    └ <module 'mysql.connector' from 'C:\\Users\\mat_i\\AppData\\Local\\Programs\\Python\\Python313\\Lib\\site-packages\\mysql\\con...
           └ <sqlalchemy.dialects.mysql.mysqlconnector.MySQLDialect_mysqlconnector object at 0x000001C8B5E2BCB0>
  File "C:\Users\mat_i\AppData\Local\Programs\Python\Python313\Lib\site-packages\mysql\connector\pooling.py", line 322, in connect
    return CMySQLConnection(*args, **kwargs)
           │                 │       └ {'host': '34.176.19.140', 'database': 'motoagency', 'user': 'matiasciafardini', 'port': 3306, 'charset': 'utf8mb4', 'buffered...
           │                 └ ()
           └ <class 'mysql.connector.connection_cext.CMySQLConnection'>
  File "C:\Users\mat_i\AppData\Local\Programs\Python\Python313\Lib\site-packages\mysql\connector\connection_cext.py", line 142, in __init__
    self.connect(**kwargs)
    │    │         └ {'host': '34.176.19.140', 'database': 'motoagency', 'user': 'matiasciafardini', 'port': 3306, 'charset': 'utf8mb4', 'buffered...
    │    └ <function MySQLConnectionAbstract.connect at 0x000001C8B5F8B920>
    └ <mysql.connector.connection_cext.CMySQLConnection object at 0x000001C8B7345010>
  File "C:\Users\mat_i\AppData\Local\Programs\Python\Python313\Lib\site-packages\mysql\connector\abstracts.py", line 1604, in connect
    self._open_connection()
    │    └ <function CMySQLConnection._open_connection at 0x000001C8B730BB00>
    └ <mysql.connector.connection_cext.CMySQLConnection object at 0x000001C8B7345010>
  File "C:\Users\mat_i\AppData\Local\Programs\Python\Python313\Lib\site-packages\mysql\connector\connection_cext.py", line 360, in _open_connection
    raise get_mysql_exception(
          └ <function get_mysql_exception at 0x000001C8B5F10AE0>

mysql.connector.errors.ProgrammingError: 1045 (28000): Access denied for user 'matiasciafardini'@'188.81.239.217' (using password: NO)


The above exception was the direct cause of the following exception:


Traceback (most recent call last):

  File "C:\Users\mat_i\OneDrive\Escritorio\App_gussoni\run.py", line 4, in <module>
    main()
    └ <function main at 0x000001C8B52F8360>

  File "C:\Users\mat_i\OneDrive\Escritorio\App_gussoni\app\ui\main.py", line 11, in main
    win = MainWindow()
          └ <class 'app.ui.main_window.MainWindow'>

  File "C:\Users\mat_i\OneDrive\Escritorio\App_gussoni\app\ui\main_window.py", line 46, in __init__
    self.pageDashboard = DashboardPage(self)
    │                    │             └ <app.ui.main_window.MainWindow(0x1c8b2a90520, name="MainWindow") at 0x000001C8B21DA780>
    │                    └ <class 'app.ui.pages.dashboard_page.DashboardPage'>
    └ <app.ui.main_window.MainWindow(0x1c8b2a90520, name="MainWindow") at 0x000001C8B21DA780>

  File "C:\Users\mat_i\OneDrive\Escritorio\App_gussoni\app\ui\pages\dashboard_page.py", line 63, in __init__
    self.refresh_data()
    │    └ <function DashboardPage.refresh_data at 0x000001C8B73431A0>
    └ <app.ui.pages.dashboard_page.DashboardPage(0x1c8b4b484e0) at 0x000001C8B734F0C0>

> File "C:\Users\mat_i\OneDrive\Escritorio\App_gussoni\app\ui\pages\dashboard_page.py", line 69, in refresh_data
    data: DashboardData = service.load_dashboard()
                          │       └ <function DashboardService.load_dashboard at 0x000001C8B5DFC040>
                          └ <app.services.dashboard_service.DashboardService object at 0x000001C8B49667B0>

  File "C:\Users\mat_i\OneDrive\Escritorio\App_gussoni\app\services\dashboard_service.py", line 21, in load_dashboard
    ventas_mes = self.ventas_repo.metrics_mes_actual()
                 │    │           └ <function VentasRepository.metrics_mes_actual at 0x000001C8B5DDBF60>
                 │    └ <app.repositories.ventas_repository.VentasRepository object at 0x000001C8B7344C20>
                 └ <app.services.dashboard_service.DashboardService object at 0x000001C8B49667B0>

  File "C:\Users\mat_i\OneDrive\Escritorio\App_gussoni\app\repositories\ventas_repository.py", line 24, in metrics_mes_actual
    row = self.db.execute(q, {"ini": first, "fin": fin}).mappings().one()
          │    │  │       │          │             └ datetime.date(2025, 11, 1)
          │    │  │       │          └ datetime.date(2025, 10, 1)
          │    │  │       └ <sqlalchemy.sql.elements.TextClause object at 0x000001C8B7344AD0>
          │    │  └ <function Session.execute at 0x000001C8B5D14220>
          │    └ <sqlalchemy.orm.session.Session object at 0x000001C8B4966A50>
          └ <app.repositories.ventas_repository.VentasRepository object at 0x000001C8B7344C20>

  File "C:\Users\mat_i\AppData\Local\Programs\Python\Python313\Lib\site-packages\sqlalchemy\orm\session.py", line 2362, in execute
    return self._execute_internal(
           │    └ <function Session._execute_internal at 0x000001C8B5D07EC0>
           └ <sqlalchemy.orm.session.Session object at 0x000001C8B4966A50>
  File "C:\Users\mat_i\AppData\Local\Programs\Python\Python313\Lib\site-packages\sqlalchemy\orm\session.py", line 2237, in _execute_internal
    conn = self._connection_for_bind(bind)
           │    │                    └ Engine(mysql+mysqlconnector://matiasciafardini:***@34.176.19.140:3306/motoagency?charset=utf8mb4)
           │    └ <function Session._connection_for_bind at 0x000001C8B5D07C40>
           └ <sqlalchemy.orm.session.Session object at 0x000001C8B4966A50>
  File "C:\Users\mat_i\AppData\Local\Programs\Python\Python313\Lib\site-packages\sqlalchemy\orm\session.py", line 2106, in _connection_for_bind
    return trans._connection_for_bind(engine, execution_options)
           │     │                    │       └ None
           │     │                    └ Engine(mysql+mysqlconnector://matiasciafardini:***@34.176.19.140:3306/motoagency?charset=utf8mb4)
           │     └ <function SessionTransaction._connection_for_bind at 0x000001C8B5D065C0>
           └ <sqlalchemy.orm.session.SessionTransaction object at 0x000001C8B5E4C250>
  File "<string>", line 2, in _connection_for_bind
  File "C:\Users\mat_i\AppData\Local\Programs\Python\Python313\Lib\site-packages\sqlalchemy\orm\state_changes.py", line 139, in _go
    ret_value = fn(self, *arg, **kw)
                │  │      │      └ {}
                │  │      └ (Engine(mysql+mysqlconnector://matiasciafardini:***@34.176.19.140:3306/motoagency?charset=utf8mb4), None)
                │  └ <sqlalchemy.orm.session.SessionTransaction object at 0x000001C8B5E4C250>
                └ <function SessionTransaction._connection_for_bind at 0x000001C8B5D06520>
  File "C:\Users\mat_i\AppData\Local\Programs\Python\Python313\Lib\site-packages\sqlalchemy\orm\session.py", line 1189, in _connection_for_bind
    conn = bind.connect()
           │    └ <function Engine.connect at 0x000001C8B595EA20>
           └ Engine(mysql+mysqlconnector://matiasciafardini:***@34.176.19.140:3306/motoagency?charset=utf8mb4)
  File "C:\Users\mat_i\AppData\Local\Programs\Python\Python313\Lib\site-packages\sqlalchemy\engine\base.py", line 3278, in connect
    return self._connection_cls(self)
           │    │               └ Engine(mysql+mysqlconnector://matiasciafardini:***@34.176.19.140:3306/motoagency?charset=utf8mb4)
           │    └ <class 'sqlalchemy.engine.base.Connection'>
           └ Engine(mysql+mysqlconnector://matiasciafardini:***@34.176.19.140:3306/motoagency?charset=utf8mb4)
  File "C:\Users\mat_i\AppData\Local\Programs\Python\Python313\Lib\site-packages\sqlalchemy\engine\base.py", line 148, in __init__
    Connection._handle_dbapi_exception_noconnection(
    │          └ <classmethod(<function Connection._handle_dbapi_exception_noconnection at 0x000001C8B595C2C0>)>
    └ <class 'sqlalchemy.engine.base.Connection'>
  File "C:\Users\mat_i\AppData\Local\Programs\Python\Python313\Lib\site-packages\sqlalchemy\engine\base.py", line 2442, in _handle_dbapi_exception_noconnection
    raise sqlalchemy_exception.with_traceback(exc_info[2]) from e
          │                    │              │                 └ ProgrammingError(1045, "1045 (28000): Access denied for user 'matiasciafardini'@'188.81.239.217' (using password: NO)", '28000')
          │                    │              └ (<class 'mysql.connector.errors.ProgrammingError'>, ProgrammingError(1045, "1045 (28000): Access denied for user 'matiasciafa...
          │                    └ <method 'with_traceback' of 'BaseException' objects>
          └ ProgrammingError("(mysql.connector.errors.ProgrammingError) 1045 (28000): Access denied for user 'matiasciafardini'@'188.81.2...
  File "C:\Users\mat_i\AppData\Local\Programs\Python\Python313\Lib\site-packages\sqlalchemy\engine\base.py", line 146, in __init__
    self._dbapi_connection = engine.raw_connection()
    │                        │      └ <function Engine.raw_connection at 0x000001C8B595EAC0>
    │                        └ Engine(mysql+mysqlconnector://matiasciafardini:***@34.176.19.140:3306/motoagency?charset=utf8mb4)
    └ <sqlalchemy.engine.base.Connection object at 0x000001C8B7344EC0>
  File "C:\Users\mat_i\AppData\Local\Programs\Python\Python313\Lib\site-packages\sqlalchemy\engine\base.py", line 3302, in raw_connection
    return self.pool.connect()
           │    │    └ <function Pool.connect at 0x000001C8B54F39C0>
           │    └ <sqlalchemy.pool.impl.QueuePool object at 0x000001C8B7344590>
           └ Engine(mysql+mysqlconnector://matiasciafardini:***@34.176.19.140:3306/motoagency?charset=utf8mb4)
  File "C:\Users\mat_i\AppData\Local\Programs\Python\Python313\Lib\site-packages\sqlalchemy\pool\base.py", line 449, in connect
    return _ConnectionFairy._checkout(self)
           │                │         └ <sqlalchemy.pool.impl.QueuePool object at 0x000001C8B7344590>
           │                └ <classmethod(<function _ConnectionFairy._checkout at 0x000001C8B5525B20>)>
           └ <class 'sqlalchemy.pool.base._ConnectionFairy'>
  File "C:\Users\mat_i\AppData\Local\Programs\Python\Python313\Lib\site-packages\sqlalchemy\pool\base.py", line 1263, in _checkout
    fairy = _ConnectionRecord.checkout(pool)
            │                 │        └ <sqlalchemy.pool.impl.QueuePool object at 0x000001C8B7344590>
            │                 └ <classmethod(<function _ConnectionRecord.checkout at 0x000001C8B5524680>)>
            └ <class 'sqlalchemy.pool.base._ConnectionRecord'>
  File "C:\Users\mat_i\AppData\Local\Programs\Python\Python313\Lib\site-packages\sqlalchemy\pool\base.py", line 712, in checkout
    rec = pool._do_get()
          │    └ <function QueuePool._do_get at 0x000001C8B5527920>
          └ <sqlalchemy.pool.impl.QueuePool object at 0x000001C8B7344590>
  File "C:\Users\mat_i\AppData\Local\Programs\Python\Python313\Lib\site-packages\sqlalchemy\pool\impl.py", line 179, in _do_get
    with util.safe_reraise():
         │    └ <class 'sqlalchemy.util.langhelpers.safe_reraise'>
         └ <module 'sqlalchemy.util' from 'C:\\Users\\mat_i\\AppData\\Local\\Programs\\Python\\Python313\\Lib\\site-packages\\sqlalchemy...
  File "C:\Users\mat_i\AppData\Local\Programs\Python\Python313\Lib\site-packages\sqlalchemy\util\langhelpers.py", line 146, in __exit__
    raise exc_value.with_traceback(exc_tb)
          │         │              └ <traceback object at 0x000001C8B734E880>
          │         └ <method 'with_traceback' of 'BaseException' objects>
          └ ProgrammingError(1045, "1045 (28000): Access denied for user 'matiasciafardini'@'188.81.239.217' (using password: NO)", '28000')
  File "C:\Users\mat_i\AppData\Local\Programs\Python\Python313\Lib\site-packages\sqlalchemy\pool\impl.py", line 177, in _do_get
    return self._create_connection()
           │    └ <function Pool._create_connection at 0x000001C8B54F3740>
           └ <sqlalchemy.pool.impl.QueuePool object at 0x000001C8B7344590>
  File "C:\Users\mat_i\AppData\Local\Programs\Python\Python313\Lib\site-packages\sqlalchemy\pool\base.py", line 390, in _create_connection
    return _ConnectionRecord(self)
           │                 └ <sqlalchemy.pool.impl.QueuePool object at 0x000001C8B7344590>
           └ <class 'sqlalchemy.pool.base._ConnectionRecord'>
  File "C:\Users\mat_i\AppData\Local\Programs\Python\Python313\Lib\site-packages\sqlalchemy\pool\base.py", line 674, in __init__
    self.__connect()
    └ <sqlalchemy.pool.base._ConnectionRecord object at 0x000001C8B1FA6E70>
  File "C:\Users\mat_i\AppData\Local\Programs\Python\Python313\Lib\site-packages\sqlalchemy\pool\base.py", line 900, in __connect
    with util.safe_reraise():
         │    └ <class 'sqlalchemy.util.langhelpers.safe_reraise'>
         └ <module 'sqlalchemy.util' from 'C:\\Users\\mat_i\\AppData\\Local\\Programs\\Python\\Python313\\Lib\\site-packages\\sqlalchemy...
  File "C:\Users\mat_i\AppData\Local\Programs\Python\Python313\Lib\site-packages\sqlalchemy\util\langhelpers.py", line 146, in __exit__
    raise exc_value.with_traceback(exc_tb)
          │         │              └ <traceback object at 0x000001C8B734E380>
          │         └ <method 'with_traceback' of 'BaseException' objects>
          └ ProgrammingError(1045, "1045 (28000): Access denied for user 'matiasciafardini'@'188.81.239.217' (using password: NO)", '28000')
  File "C:\Users\mat_i\AppData\Local\Programs\Python\Python313\Lib\site-packages\sqlalchemy\pool\base.py", line 896, in __connect
    self.dbapi_connection = connection = pool._invoke_creator(self)
    │    │                               │    │               └ <sqlalchemy.pool.base._ConnectionRecord object at 0x000001C8B1FA6E70>
    │    │                               │    └ <function create_engine.<locals>.connect at 0x000001C8B5DFCAE0>
    │    │                               └ <sqlalchemy.pool.impl.QueuePool object at 0x000001C8B7344590>
    │    └ <member 'dbapi_connection' of '_ConnectionRecord' objects>
    └ <sqlalchemy.pool.base._ConnectionRecord object at 0x000001C8B1FA6E70>
  File "C:\Users\mat_i\AppData\Local\Programs\Python\Python313\Lib\site-packages\sqlalchemy\engine\create.py", line 643, in connect
    return dialect.connect(*cargs, **cparams)
           │       │        │        └ {'host': '34.176.19.140', 'database': 'motoagency', 'user': 'matiasciafardini', 'port': 3306, 'charset': 'utf8mb4', 'buffered...
           │       │        └ []
           │       └ <function DefaultDialect.connect at 0x000001C8B5A4DF80>
           └ <sqlalchemy.dialects.mysql.mysqlconnector.MySQLDialect_mysqlconnector object at 0x000001C8B5E2BCB0>
  File "C:\Users\mat_i\AppData\Local\Programs\Python\Python313\Lib\site-packages\sqlalchemy\engine\default.py", line 621, in connect
    return self.loaded_dbapi.connect(*cargs, **cparams)
           │    │            │        │        └ {'host': '34.176.19.140', 'database': 'motoagency', 'user': 'matiasciafardini', 'port': 3306, 'charset': 'utf8mb4', 'buffered...
           │    │            │        └ ()
           │    │            └ <function connect at 0x000001C8B7340040>
           │    └ <module 'mysql.connector' from 'C:\\Users\\mat_i\\AppData\\Local\\Programs\\Python\\Python313\\Lib\\site-packages\\mysql\\con...
           └ <sqlalchemy.dialects.mysql.mysqlconnector.MySQLDialect_mysqlconnector object at 0x000001C8B5E2BCB0>
  File "C:\Users\mat_i\AppData\Local\Programs\Python\Python313\Lib\site-packages\mysql\connector\pooling.py", line 322, in connect
    return CMySQLConnection(*args, **kwargs)
           │                 │       └ {'host': '34.176.19.140', 'database': 'motoagency', 'user': 'matiasciafardini', 'port': 3306, 'charset': 'utf8mb4', 'buffered...
           │                 └ ()
           └ <class 'mysql.connector.connection_cext.CMySQLConnection'>
  File "C:\Users\mat_i\AppData\Local\Programs\Python\Python313\Lib\site-packages\mysql\connector\connection_cext.py", line 142, in __init__
    self.connect(**kwargs)
    │    │         └ {'host': '34.176.19.140', 'database': 'motoagency', 'user': 'matiasciafardini', 'port': 3306, 'charset': 'utf8mb4', 'buffered...
    │    └ <function MySQLConnectionAbstract.connect at 0x000001C8B5F8B920>
    └ <mysql.connector.connection_cext.CMySQLConnection object at 0x000001C8B7345010>
  File "C:\Users\mat_i\AppData\Local\Programs\Python\Python313\Lib\site-packages\mysql\connector\abstracts.py", line 1604, in connect
    self._open_connection()
    │    └ <function CMySQLConnection._open_connection at 0x000001C8B730BB00>
    └ <mysql.connector.connection_cext.CMySQLConnection object at 0x000001C8B7345010>
  File "C:\Users\mat_i\AppData\Local\Programs\Python\Python313\Lib\site-packages\mysql\connector\connection_cext.py", line 360, in _open_connection
    raise get_mysql_exception(
          └ <function get_mysql_exception at 0x000001C8B5F10AE0>

sqlalchemy.exc.ProgrammingError: (mysql.connector.errors.ProgrammingError) 1045 (28000): Access denied for user 'matiasciafardini'@'188.81.239.217' (using password: NO)
(Background on this error at: https://sqlalche.me/e/20/f405)
2025-10-10 03:56:31.002 | ERROR    | app.ui.pages.dashboard_page:refresh_data:91 - No se pudo cargar dashboard: (mysql.connector.errors.ProgrammingError) 1045 (28000): Access denied for user 'matiasciafardini'@'188.81.239.217' (using password: NO)
(Background on this error at: https://sqlalche.me/e/20/f405)
Traceback (most recent call last):

  File "C:\Users\mat_i\AppData\Local\Programs\Python\Python313\Lib\site-packages\mysql\connector\connection_cext.py", line 354, in _open_connection
    self._cmysql.connect(**cnx_kwargs)
    │    │       │         └ {'host': '34.176.19.140', 'user': 'matiasciafardini', 'password': '', 'password1': '', 'password2': '', 'password3': '', 'dat...
    │    │       └ <method 'connect' of '_mysql_connector.MySQL' objects>
    │    └ <_mysql_connector.MySQL object at 0x000002027D512AE0>
    └ <mysql.connector.connection_cext.CMySQLConnection object at 0x000002027E267CB0>

_mysql_connector.MySQLInterfaceError: Access denied for user 'matiasciafardini'@'188.81.239.217' (using password: NO)


The above exception was the direct cause of the following exception:


Traceback (most recent call last):

  File "C:\Users\mat_i\AppData\Local\Programs\Python\Python313\Lib\site-packages\sqlalchemy\engine\base.py", line 146, in __init__
    self._dbapi_connection = engine.raw_connection()
    │                        │      └ <function Engine.raw_connection at 0x000002027DD02480>
    │                        └ Engine(mysql+mysqlconnector://matiasciafardini:***@34.176.19.140:3306/motoagency?charset=utf8mb4)
    └ <sqlalchemy.engine.base.Connection object at 0x000002027E267B60>
  File "C:\Users\mat_i\AppData\Local\Programs\Python\Python313\Lib\site-packages\sqlalchemy\engine\base.py", line 3302, in raw_connection
    return self.pool.connect()
           │    │    └ <function Pool.connect at 0x000002027D897380>
           │    └ <sqlalchemy.pool.impl.QueuePool object at 0x000002027E267380>
           └ Engine(mysql+mysqlconnector://matiasciafardini:***@34.176.19.140:3306/motoagency?charset=utf8mb4)
  File "C:\Users\mat_i\AppData\Local\Programs\Python\Python313\Lib\site-packages\sqlalchemy\pool\base.py", line 449, in connect
    return _ConnectionFairy._checkout(self)
           │                │         └ <sqlalchemy.pool.impl.QueuePool object at 0x000002027E267380>
           │                └ <classmethod(<function _ConnectionFairy._checkout at 0x000002027D8D14E0>)>
           └ <class 'sqlalchemy.pool.base._ConnectionFairy'>
  File "C:\Users\mat_i\AppData\Local\Programs\Python\Python313\Lib\site-packages\sqlalchemy\pool\base.py", line 1263, in _checkout
    fairy = _ConnectionRecord.checkout(pool)
            │                 │        └ <sqlalchemy.pool.impl.QueuePool object at 0x000002027E267380>
            │                 └ <classmethod(<function _ConnectionRecord.checkout at 0x000002027D8D0040>)>
            └ <class 'sqlalchemy.pool.base._ConnectionRecord'>
  File "C:\Users\mat_i\AppData\Local\Programs\Python\Python313\Lib\site-packages\sqlalchemy\pool\base.py", line 712, in checkout
    rec = pool._do_get()
          │    └ <function QueuePool._do_get at 0x000002027D8D32E0>
          └ <sqlalchemy.pool.impl.QueuePool object at 0x000002027E267380>
  File "C:\Users\mat_i\AppData\Local\Programs\Python\Python313\Lib\site-packages\sqlalchemy\pool\impl.py", line 179, in _do_get
    with util.safe_reraise():
         │    └ <class 'sqlalchemy.util.langhelpers.safe_reraise'>
         └ <module 'sqlalchemy.util' from 'C:\\Users\\mat_i\\AppData\\Local\\Programs\\Python\\Python313\\Lib\\site-packages\\sqlalchemy...
  File "C:\Users\mat_i\AppData\Local\Programs\Python\Python313\Lib\site-packages\sqlalchemy\util\langhelpers.py", line 146, in __exit__
    raise exc_value.with_traceback(exc_tb)
          │         │              └ <traceback object at 0x000002027E717140>
          │         └ <method 'with_traceback' of 'BaseException' objects>
          └ ProgrammingError(1045, "1045 (28000): Access denied for user 'matiasciafardini'@'188.81.239.217' (using password: NO)", '28000')
  File "C:\Users\mat_i\AppData\Local\Programs\Python\Python313\Lib\site-packages\sqlalchemy\pool\impl.py", line 177, in _do_get
    return self._create_connection()
           │    └ <function Pool._create_connection at 0x000002027D897100>
           └ <sqlalchemy.pool.impl.QueuePool object at 0x000002027E267380>
  File "C:\Users\mat_i\AppData\Local\Programs\Python\Python313\Lib\site-packages\sqlalchemy\pool\base.py", line 390, in _create_connection
    return _ConnectionRecord(self)
           │                 └ <sqlalchemy.pool.impl.QueuePool object at 0x000002027E267380>
           └ <class 'sqlalchemy.pool.base._ConnectionRecord'>
  File "C:\Users\mat_i\AppData\Local\Programs\Python\Python313\Lib\site-packages\sqlalchemy\pool\base.py", line 674, in __init__
    self.__connect()
    └ <sqlalchemy.pool.base._ConnectionRecord object at 0x000002027A406E70>
  File "C:\Users\mat_i\AppData\Local\Programs\Python\Python313\Lib\site-packages\sqlalchemy\pool\base.py", line 900, in __connect
    with util.safe_reraise():
         │    └ <class 'sqlalchemy.util.langhelpers.safe_reraise'>
         └ <module 'sqlalchemy.util' from 'C:\\Users\\mat_i\\AppData\\Local\\Programs\\Python\\Python313\\Lib\\site-packages\\sqlalchemy...
  File "C:\Users\mat_i\AppData\Local\Programs\Python\Python313\Lib\site-packages\sqlalchemy\util\langhelpers.py", line 146, in __exit__
    raise exc_value.with_traceback(exc_tb)
          │         │              └ <traceback object at 0x000002027DE755C0>
          │         └ <method 'with_traceback' of 'BaseException' objects>
          └ ProgrammingError(1045, "1045 (28000): Access denied for user 'matiasciafardini'@'188.81.239.217' (using password: NO)", '28000')
  File "C:\Users\mat_i\AppData\Local\Programs\Python\Python313\Lib\site-packages\sqlalchemy\pool\base.py", line 896, in __connect
    self.dbapi_connection = connection = pool._invoke_creator(self)
    │    │                               │    │               └ <sqlalchemy.pool.base._ConnectionRecord object at 0x000002027A406E70>
    │    │                               │    └ <function create_engine.<locals>.connect at 0x000002027E1A8720>
    │    │                               └ <sqlalchemy.pool.impl.QueuePool object at 0x000002027E267380>
    │    └ <member 'dbapi_connection' of '_ConnectionRecord' objects>
    └ <sqlalchemy.pool.base._ConnectionRecord object at 0x000002027A406E70>
  File "C:\Users\mat_i\AppData\Local\Programs\Python\Python313\Lib\site-packages\sqlalchemy\engine\create.py", line 643, in connect
    return dialect.connect(*cargs, **cparams)
           │       │        │        └ {'host': '34.176.19.140', 'database': 'motoagency', 'user': 'matiasciafardini', 'port': 3306, 'charset': 'utf8mb4', 'buffered...
           │       │        └ []
           │       └ <function DefaultDialect.connect at 0x000002027DE0D940>
           └ <sqlalchemy.dialects.mysql.mysqlconnector.MySQLDialect_mysqlconnector object at 0x000002027E266F90>
  File "C:\Users\mat_i\AppData\Local\Programs\Python\Python313\Lib\site-packages\sqlalchemy\engine\default.py", line 621, in connect
    return self.loaded_dbapi.connect(*cargs, **cparams)
           │    │            │        │        └ {'host': '34.176.19.140', 'database': 'motoagency', 'user': 'matiasciafardini', 'port': 3306, 'charset': 'utf8mb4', 'buffered...
           │    │            │        └ ()
           │    │            └ <function connect at 0x000002027E6EB2E0>
           │    └ <module 'mysql.connector' from 'C:\\Users\\mat_i\\AppData\\Local\\Programs\\Python\\Python313\\Lib\\site-packages\\mysql\\con...
           └ <sqlalchemy.dialects.mysql.mysqlconnector.MySQLDialect_mysqlconnector object at 0x000002027E266F90>
  File "C:\Users\mat_i\AppData\Local\Programs\Python\Python313\Lib\site-packages\mysql\connector\pooling.py", line 322, in connect
    return CMySQLConnection(*args, **kwargs)
           │                 │       └ {'host': '34.176.19.140', 'database': 'motoagency', 'user': 'matiasciafardini', 'port': 3306, 'charset': 'utf8mb4', 'buffered...
           │                 └ ()
           └ <class 'mysql.connector.connection_cext.CMySQLConnection'>
  File "C:\Users\mat_i\AppData\Local\Programs\Python\Python313\Lib\site-packages\mysql\connector\connection_cext.py", line 142, in __init__
    self.connect(**kwargs)
    │    │         └ {'host': '34.176.19.140', 'database': 'motoagency', 'user': 'matiasciafardini', 'port': 3306, 'charset': 'utf8mb4', 'buffered...
    │    └ <function MySQLConnectionAbstract.connect at 0x000002027E33F420>
    └ <mysql.connector.connection_cext.CMySQLConnection object at 0x000002027E267CB0>
  File "C:\Users\mat_i\AppData\Local\Programs\Python\Python313\Lib\site-packages\mysql\connector\abstracts.py", line 1604, in connect
    self._open_connection()
    │    └ <function CMySQLConnection._open_connection at 0x000002027E6C3600>
    └ <mysql.connector.connection_cext.CMySQLConnection object at 0x000002027E267CB0>
  File "C:\Users\mat_i\AppData\Local\Programs\Python\Python313\Lib\site-packages\mysql\connector\connection_cext.py", line 360, in _open_connection
    raise get_mysql_exception(
          └ <function get_mysql_exception at 0x000002027E2C45E0>

mysql.connector.errors.ProgrammingError: 1045 (28000): Access denied for user 'matiasciafardini'@'188.81.239.217' (using password: NO)


The above exception was the direct cause of the following exception:


Traceback (most recent call last):

  File "C:\Users\mat_i\OneDrive\Escritorio\App_gussoni\run.py", line 4, in <module>
    main()
    └ <function main at 0x000002027CDF5760>

  File "C:\Users\mat_i\OneDrive\Escritorio\App_gussoni\app\ui\main.py", line 11, in main
    win = MainWindow()
          └ <class 'app.ui.main_window.MainWindow'>

  File "C:\Users\mat_i\OneDrive\Escritorio\App_gussoni\app\ui\main_window.py", line 24, in __init__
    self.pageDashboard = DashboardPage(self)
    │                    │             └ <app.ui.main_window.MainWindow(0x2027ad85c10, name="MainWindow") at 0x000002027DB04F80>
    │                    └ <class 'app.ui.pages.dashboard_page.DashboardPage'>
    └ <app.ui.main_window.MainWindow(0x2027ad85c10, name="MainWindow") at 0x000002027DB04F80>

  File "C:\Users\mat_i\OneDrive\Escritorio\App_gussoni\app\ui\pages\dashboard_page.py", line 83, in __init__
    self.refresh_data()
    │    └ <function DashboardPage.refresh_data at 0x000002027E702F20>
    └ <app.ui.pages.dashboard_page.DashboardPage(0x2027d64d990) at 0x000002027E714540>

> File "C:\Users\mat_i\OneDrive\Escritorio\App_gussoni\app\ui\pages\dashboard_page.py", line 89, in refresh_data
    data: DashboardData = service.load_dashboard()
                          │       └ <function DashboardService.load_dashboard at 0x000002027E187EC0>
                          └ <app.services.dashboard_service.DashboardService object at 0x000002027CD467B0>

  File "C:\Users\mat_i\OneDrive\Escritorio\App_gussoni\app\services\dashboard_service.py", line 23, in load_dashboard
    ventas_mes = self.ventas_repo.metrics_mes_actual()
                 │    │           └ <function VentasRepository.metrics_mes_actual at 0x000002027E187B00>
                 │    └ <app.repositories.ventas_repository.VentasRepository object at 0x000002027CDFC1A0>
                 └ <app.services.dashboard_service.DashboardService object at 0x000002027CD467B0>

  File "C:\Users\mat_i\OneDrive\Escritorio\App_gussoni\app\repositories\ventas_repository.py", line 16, in metrics_mes_actual
    row = self.db.execute(text("""
          │    │  │       └ <function text at 0x000002027DCA4FE0>
          │    │  └ <function Session.execute at 0x000002027E0B3BA0>
          │    └ <sqlalchemy.orm.session.Session object at 0x000002027CD46A50>
          └ <app.repositories.ventas_repository.VentasRepository object at 0x000002027CDFC1A0>

  File "C:\Users\mat_i\AppData\Local\Programs\Python\Python313\Lib\site-packages\sqlalchemy\orm\session.py", line 2362, in execute
    return self._execute_internal(
           │    └ <function Session._execute_internal at 0x000002027E0B3880>
           └ <sqlalchemy.orm.session.Session object at 0x000002027CD46A50>
  File "C:\Users\mat_i\AppData\Local\Programs\Python\Python313\Lib\site-packages\sqlalchemy\orm\session.py", line 2237, in _execute_internal
    conn = self._connection_for_bind(bind)
           │    │                    └ Engine(mysql+mysqlconnector://matiasciafardini:***@34.176.19.140:3306/motoagency?charset=utf8mb4)
           │    └ <function Session._connection_for_bind at 0x000002027E0B3600>
           └ <sqlalchemy.orm.session.Session object at 0x000002027CD46A50>
  File "C:\Users\mat_i\AppData\Local\Programs\Python\Python313\Lib\site-packages\sqlalchemy\orm\session.py", line 2106, in _connection_for_bind
    return trans._connection_for_bind(engine, execution_options)
           │     │                    │       └ None
           │     │                    └ Engine(mysql+mysqlconnector://matiasciafardini:***@34.176.19.140:3306/motoagency?charset=utf8mb4)
           │     └ <function SessionTransaction._connection_for_bind at 0x000002027E0B1F80>
           └ <sqlalchemy.orm.session.SessionTransaction object at 0x000002027DAED010>
  File "<string>", line 2, in _connection_for_bind
  File "C:\Users\mat_i\AppData\Local\Programs\Python\Python313\Lib\site-packages\sqlalchemy\orm\state_changes.py", line 139, in _go
    ret_value = fn(self, *arg, **kw)
                │  │      │      └ {}
                │  │      └ (Engine(mysql+mysqlconnector://matiasciafardini:***@34.176.19.140:3306/motoagency?charset=utf8mb4), None)
                │  └ <sqlalchemy.orm.session.SessionTransaction object at 0x000002027DAED010>
                └ <function SessionTransaction._connection_for_bind at 0x000002027E0B1EE0>
  File "C:\Users\mat_i\AppData\Local\Programs\Python\Python313\Lib\site-packages\sqlalchemy\orm\session.py", line 1189, in _connection_for_bind
    conn = bind.connect()
           │    └ <function Engine.connect at 0x000002027DD023E0>
           └ Engine(mysql+mysqlconnector://matiasciafardini:***@34.176.19.140:3306/motoagency?charset=utf8mb4)
  File "C:\Users\mat_i\AppData\Local\Programs\Python\Python313\Lib\site-packages\sqlalchemy\engine\base.py", line 3278, in connect
    return self._connection_cls(self)
           │    │               └ Engine(mysql+mysqlconnector://matiasciafardini:***@34.176.19.140:3306/motoagency?charset=utf8mb4)
           │    └ <class 'sqlalchemy.engine.base.Connection'>
           └ Engine(mysql+mysqlconnector://matiasciafardini:***@34.176.19.140:3306/motoagency?charset=utf8mb4)
  File "C:\Users\mat_i\AppData\Local\Programs\Python\Python313\Lib\site-packages\sqlalchemy\engine\base.py", line 148, in __init__
    Connection._handle_dbapi_exception_noconnection(
    │          └ <classmethod(<function Connection._handle_dbapi_exception_noconnection at 0x000002027DCF7C40>)>
    └ <class 'sqlalchemy.engine.base.Connection'>
  File "C:\Users\mat_i\AppData\Local\Programs\Python\Python313\Lib\site-packages\sqlalchemy\engine\base.py", line 2442, in _handle_dbapi_exception_noconnection
    raise sqlalchemy_exception.with_traceback(exc_info[2]) from e
          │                    │              │                 └ ProgrammingError(1045, "1045 (28000): Access denied for user 'matiasciafardini'@'188.81.239.217' (using password: NO)", '28000')
          │                    │              └ (<class 'mysql.connector.errors.ProgrammingError'>, ProgrammingError(1045, "1045 (28000): Access denied for user 'matiasciafa...
          │                    └ <method 'with_traceback' of 'BaseException' objects>
          └ ProgrammingError("(mysql.connector.errors.ProgrammingError) 1045 (28000): Access denied for user 'matiasciafardini'@'188.81.2...
  File "C:\Users\mat_i\AppData\Local\Programs\Python\Python313\Lib\site-packages\sqlalchemy\engine\base.py", line 146, in __init__
    self._dbapi_connection = engine.raw_connection()
    │                        │      └ <function Engine.raw_connection at 0x000002027DD02480>
    │                        └ Engine(mysql+mysqlconnector://matiasciafardini:***@34.176.19.140:3306/motoagency?charset=utf8mb4)
    └ <sqlalchemy.engine.base.Connection object at 0x000002027E267B60>
  File "C:\Users\mat_i\AppData\Local\Programs\Python\Python313\Lib\site-packages\sqlalchemy\engine\base.py", line 3302, in raw_connection
    return self.pool.connect()
           │    │    └ <function Pool.connect at 0x000002027D897380>
           │    └ <sqlalchemy.pool.impl.QueuePool object at 0x000002027E267380>
           └ Engine(mysql+mysqlconnector://matiasciafardini:***@34.176.19.140:3306/motoagency?charset=utf8mb4)
  File "C:\Users\mat_i\AppData\Local\Programs\Python\Python313\Lib\site-packages\sqlalchemy\pool\base.py", line 449, in connect
    return _ConnectionFairy._checkout(self)
           │                │         └ <sqlalchemy.pool.impl.QueuePool object at 0x000002027E267380>
           │                └ <classmethod(<function _ConnectionFairy._checkout at 0x000002027D8D14E0>)>
           └ <class 'sqlalchemy.pool.base._ConnectionFairy'>
  File "C:\Users\mat_i\AppData\Local\Programs\Python\Python313\Lib\site-packages\sqlalchemy\pool\base.py", line 1263, in _checkout
    fairy = _ConnectionRecord.checkout(pool)
            │                 │        └ <sqlalchemy.pool.impl.QueuePool object at 0x000002027E267380>
            │                 └ <classmethod(<function _ConnectionRecord.checkout at 0x000002027D8D0040>)>
            └ <class 'sqlalchemy.pool.base._ConnectionRecord'>
  File "C:\Users\mat_i\AppData\Local\Programs\Python\Python313\Lib\site-packages\sqlalchemy\pool\base.py", line 712, in checkout
    rec = pool._do_get()
          │    └ <function QueuePool._do_get at 0x000002027D8D32E0>
          └ <sqlalchemy.pool.impl.QueuePool object at 0x000002027E267380>
  File "C:\Users\mat_i\AppData\Local\Programs\Python\Python313\Lib\site-packages\sqlalchemy\pool\impl.py", line 179, in _do_get
    with util.safe_reraise():
         │    └ <class 'sqlalchemy.util.langhelpers.safe_reraise'>
         └ <module 'sqlalchemy.util' from 'C:\\Users\\mat_i\\AppData\\Local\\Programs\\Python\\Python313\\Lib\\site-packages\\sqlalchemy...
  File "C:\Users\mat_i\AppData\Local\Programs\Python\Python313\Lib\site-packages\sqlalchemy\util\langhelpers.py", line 146, in __exit__
    raise exc_value.with_traceback(exc_tb)
          │         │              └ <traceback object at 0x000002027E717140>
          │         └ <method 'with_traceback' of 'BaseException' objects>
          └ ProgrammingError(1045, "1045 (28000): Access denied for user 'matiasciafardini'@'188.81.239.217' (using password: NO)", '28000')
  File "C:\Users\mat_i\AppData\Local\Programs\Python\Python313\Lib\site-packages\sqlalchemy\pool\impl.py", line 177, in _do_get
    return self._create_connection()
           │    └ <function Pool._create_connection at 0x000002027D897100>
           └ <sqlalchemy.pool.impl.QueuePool object at 0x000002027E267380>
  File "C:\Users\mat_i\AppData\Local\Programs\Python\Python313\Lib\site-packages\sqlalchemy\pool\base.py", line 390, in _create_connection
    return _ConnectionRecord(self)
           │                 └ <sqlalchemy.pool.impl.QueuePool object at 0x000002027E267380>
           └ <class 'sqlalchemy.pool.base._ConnectionRecord'>
  File "C:\Users\mat_i\AppData\Local\Programs\Python\Python313\Lib\site-packages\sqlalchemy\pool\base.py", line 674, in __init__
    self.__connect()
    └ <sqlalchemy.pool.base._ConnectionRecord object at 0x000002027A406E70>
  File "C:\Users\mat_i\AppData\Local\Programs\Python\Python313\Lib\site-packages\sqlalchemy\pool\base.py", line 900, in __connect
    with util.safe_reraise():
         │    └ <class 'sqlalchemy.util.langhelpers.safe_reraise'>
         └ <module 'sqlalchemy.util' from 'C:\\Users\\mat_i\\AppData\\Local\\Programs\\Python\\Python313\\Lib\\site-packages\\sqlalchemy...
  File "C:\Users\mat_i\AppData\Local\Programs\Python\Python313\Lib\site-packages\sqlalchemy\util\langhelpers.py", line 146, in __exit__
    raise exc_value.with_traceback(exc_tb)
          │         │              └ <traceback object at 0x000002027DE755C0>
          │         └ <method 'with_traceback' of 'BaseException' objects>
          └ ProgrammingError(1045, "1045 (28000): Access denied for user 'matiasciafardini'@'188.81.239.217' (using password: NO)", '28000')
  File "C:\Users\mat_i\AppData\Local\Programs\Python\Python313\Lib\site-packages\sqlalchemy\pool\base.py", line 896, in __connect
    self.dbapi_connection = connection = pool._invoke_creator(self)
    │    │                               │    │               └ <sqlalchemy.pool.base._ConnectionRecord object at 0x000002027A406E70>
    │    │                               │    └ <function create_engine.<locals>.connect at 0x000002027E1A8720>
    │    │                               └ <sqlalchemy.pool.impl.QueuePool object at 0x000002027E267380>
    │    └ <member 'dbapi_connection' of '_ConnectionRecord' objects>
    └ <sqlalchemy.pool.base._ConnectionRecord object at 0x000002027A406E70>
  File "C:\Users\mat_i\AppData\Local\Programs\Python\Python313\Lib\site-packages\sqlalchemy\engine\create.py", line 643, in connect
    return dialect.connect(*cargs, **cparams)
           │       │        │        └ {'host': '34.176.19.140', 'database': 'motoagency', 'user': 'matiasciafardini', 'port': 3306, 'charset': 'utf8mb4', 'buffered...
           │       │        └ []
           │       └ <function DefaultDialect.connect at 0x000002027DE0D940>
           └ <sqlalchemy.dialects.mysql.mysqlconnector.MySQLDialect_mysqlconnector object at 0x000002027E266F90>
  File "C:\Users\mat_i\AppData\Local\Programs\Python\Python313\Lib\site-packages\sqlalchemy\engine\default.py", line 621, in connect
    return self.loaded_dbapi.connect(*cargs, **cparams)
           │    │            │        │        └ {'host': '34.176.19.140', 'database': 'motoagency', 'user': 'matiasciafardini', 'port': 3306, 'charset': 'utf8mb4', 'buffered...
           │    │            │        └ ()
           │    │            └ <function connect at 0x000002027E6EB2E0>
           │    └ <module 'mysql.connector' from 'C:\\Users\\mat_i\\AppData\\Local\\Programs\\Python\\Python313\\Lib\\site-packages\\mysql\\con...
           └ <sqlalchemy.dialects.mysql.mysqlconnector.MySQLDialect_mysqlconnector object at 0x000002027E266F90>
  File "C:\Users\mat_i\AppData\Local\Programs\Python\Python313\Lib\site-packages\mysql\connector\pooling.py", line 322, in connect
    return CMySQLConnection(*args, **kwargs)
           │                 │       └ {'host': '34.176.19.140', 'database': 'motoagency', 'user': 'matiasciafardini', 'port': 3306, 'charset': 'utf8mb4', 'buffered...
           │                 └ ()
           └ <class 'mysql.connector.connection_cext.CMySQLConnection'>
  File "C:\Users\mat_i\AppData\Local\Programs\Python\Python313\Lib\site-packages\mysql\connector\connection_cext.py", line 142, in __init__
    self.connect(**kwargs)
    │    │         └ {'host': '34.176.19.140', 'database': 'motoagency', 'user': 'matiasciafardini', 'port': 3306, 'charset': 'utf8mb4', 'buffered...
    │    └ <function MySQLConnectionAbstract.connect at 0x000002027E33F420>
    └ <mysql.connector.connection_cext.CMySQLConnection object at 0x000002027E267CB0>
  File "C:\Users\mat_i\AppData\Local\Programs\Python\Python313\Lib\site-packages\mysql\connector\abstracts.py", line 1604, in connect
    self._open_connection()
    │    └ <function CMySQLConnection._open_connection at 0x000002027E6C3600>
    └ <mysql.connector.connection_cext.CMySQLConnection object at 0x000002027E267CB0>
  File "C:\Users\mat_i\AppData\Local\Programs\Python\Python313\Lib\site-packages\mysql\connector\connection_cext.py", line 360, in _open_connection
    raise get_mysql_exception(
          └ <function get_mysql_exception at 0x000002027E2C45E0>

sqlalchemy.exc.ProgrammingError: (mysql.connector.errors.ProgrammingError) 1045 (28000): Access denied for user 'matiasciafardini'@'188.81.239.217' (using password: NO)
(Background on this error at: https://sqlalche.me/e/20/f405)
2025-10-10 03:59:14.360 | ERROR    | app.ui.pages.dashboard_page:refresh_data:91 - No se pudo cargar dashboard: (mysql.connector.errors.ProgrammingError) 1045 (28000): Access denied for user 'matiasciafardini'@'188.81.239.217' (using password: NO)
(Background on this error at: https://sqlalche.me/e/20/f405)
Traceback (most recent call last):

  File "C:\Users\mat_i\AppData\Local\Programs\Python\Python313\Lib\site-packages\mysql\connector\connection_cext.py", line 354, in _open_connection
    self._cmysql.connect(**cnx_kwargs)
    │    │       │         └ {'host': '34.176.19.140', 'user': 'matiasciafardini', 'password': '', 'password1': '', 'password2': '', 'password3': '', 'dat...
    │    │       └ <method 'connect' of '_mysql_connector.MySQL' objects>
    │    └ <_mysql_connector.MySQL object at 0x000001A75AA69C50>
    └ <mysql.connector.connection_cext.CMySQLConnection object at 0x000001A75BEB5D30>

_mysql_connector.MySQLInterfaceError: Access denied for user 'matiasciafardini'@'188.81.239.217' (using password: NO)


The above exception was the direct cause of the following exception:


Traceback (most recent call last):

  File "C:\Users\mat_i\AppData\Local\Programs\Python\Python313\Lib\site-packages\sqlalchemy\engine\base.py", line 146, in __init__
    self._dbapi_connection = engine.raw_connection()
    │                        │      └ <function Engine.raw_connection at 0x000001A75B49E340>
    │                        └ Engine(mysql+mysqlconnector://matiasciafardini:***@34.176.19.140:3306/motoagency?charset=utf8mb4)
    └ <sqlalchemy.engine.base.Connection object at 0x000001A75BEB5BE0>
  File "C:\Users\mat_i\AppData\Local\Programs\Python\Python313\Lib\site-packages\sqlalchemy\engine\base.py", line 3302, in raw_connection
    return self.pool.connect()
           │    │    └ <function Pool.connect at 0x000001A75B037240>
           │    └ <sqlalchemy.pool.impl.QueuePool object at 0x000001A75B9FF380>
           └ Engine(mysql+mysqlconnector://matiasciafardini:***@34.176.19.140:3306/motoagency?charset=utf8mb4)
  File "C:\Users\mat_i\AppData\Local\Programs\Python\Python313\Lib\site-packages\sqlalchemy\pool\base.py", line 449, in connect
    return _ConnectionFairy._checkout(self)
           │                │         └ <sqlalchemy.pool.impl.QueuePool object at 0x000001A75B9FF380>
           │                └ <classmethod(<function _ConnectionFairy._checkout at 0x000001A75B0693A0>)>
           └ <class 'sqlalchemy.pool.base._ConnectionFairy'>
  File "C:\Users\mat_i\AppData\Local\Programs\Python\Python313\Lib\site-packages\sqlalchemy\pool\base.py", line 1263, in _checkout
    fairy = _ConnectionRecord.checkout(pool)
            │                 │        └ <sqlalchemy.pool.impl.QueuePool object at 0x000001A75B9FF380>
            │                 └ <classmethod(<function _ConnectionRecord.checkout at 0x000001A75B037EC0>)>
            └ <class 'sqlalchemy.pool.base._ConnectionRecord'>
  File "C:\Users\mat_i\AppData\Local\Programs\Python\Python313\Lib\site-packages\sqlalchemy\pool\base.py", line 712, in checkout
    rec = pool._do_get()
          │    └ <function QueuePool._do_get at 0x000001A75B06B1A0>
          └ <sqlalchemy.pool.impl.QueuePool object at 0x000001A75B9FF380>
  File "C:\Users\mat_i\AppData\Local\Programs\Python\Python313\Lib\site-packages\sqlalchemy\pool\impl.py", line 179, in _do_get
    with util.safe_reraise():
         │    └ <class 'sqlalchemy.util.langhelpers.safe_reraise'>
         └ <module 'sqlalchemy.util' from 'C:\\Users\\mat_i\\AppData\\Local\\Programs\\Python\\Python313\\Lib\\site-packages\\sqlalchemy...
  File "C:\Users\mat_i\AppData\Local\Programs\Python\Python313\Lib\site-packages\sqlalchemy\util\langhelpers.py", line 146, in __exit__
    raise exc_value.with_traceback(exc_tb)
          │         │              └ <traceback object at 0x000001A75BEF6440>
          │         └ <method 'with_traceback' of 'BaseException' objects>
          └ ProgrammingError(1045, "1045 (28000): Access denied for user 'matiasciafardini'@'188.81.239.217' (using password: NO)", '28000')
  File "C:\Users\mat_i\AppData\Local\Programs\Python\Python313\Lib\site-packages\sqlalchemy\pool\impl.py", line 177, in _do_get
    return self._create_connection()
           │    └ <function Pool._create_connection at 0x000001A75B036FC0>
           └ <sqlalchemy.pool.impl.QueuePool object at 0x000001A75B9FF380>
  File "C:\Users\mat_i\AppData\Local\Programs\Python\Python313\Lib\site-packages\sqlalchemy\pool\base.py", line 390, in _create_connection
    return _ConnectionRecord(self)
           │                 └ <sqlalchemy.pool.impl.QueuePool object at 0x000001A75B9FF380>
           └ <class 'sqlalchemy.pool.base._ConnectionRecord'>
  File "C:\Users\mat_i\AppData\Local\Programs\Python\Python313\Lib\site-packages\sqlalchemy\pool\base.py", line 674, in __init__
    self.__connect()
    └ <sqlalchemy.pool.base._ConnectionRecord object at 0x000001A757A46E70>
  File "C:\Users\mat_i\AppData\Local\Programs\Python\Python313\Lib\site-packages\sqlalchemy\pool\base.py", line 900, in __connect
    with util.safe_reraise():
         │    └ <class 'sqlalchemy.util.langhelpers.safe_reraise'>
         └ <module 'sqlalchemy.util' from 'C:\\Users\\mat_i\\AppData\\Local\\Programs\\Python\\Python313\\Lib\\site-packages\\sqlalchemy...
  File "C:\Users\mat_i\AppData\Local\Programs\Python\Python313\Lib\site-packages\sqlalchemy\util\langhelpers.py", line 146, in __exit__
    raise exc_value.with_traceback(exc_tb)
          │         │              └ <traceback object at 0x000001A75BEF5D40>
          │         └ <method 'with_traceback' of 'BaseException' objects>
          └ ProgrammingError(1045, "1045 (28000): Access denied for user 'matiasciafardini'@'188.81.239.217' (using password: NO)", '28000')
  File "C:\Users\mat_i\AppData\Local\Programs\Python\Python313\Lib\site-packages\sqlalchemy\pool\base.py", line 896, in __connect
    self.dbapi_connection = connection = pool._invoke_creator(self)
    │    │                               │    │               └ <sqlalchemy.pool.base._ConnectionRecord object at 0x000001A757A46E70>
    │    │                               │    └ <function create_engine.<locals>.connect at 0x000001A75B9385E0>
    │    │                               └ <sqlalchemy.pool.impl.QueuePool object at 0x000001A75B9FF380>
    │    └ <member 'dbapi_connection' of '_ConnectionRecord' objects>
    └ <sqlalchemy.pool.base._ConnectionRecord object at 0x000001A757A46E70>
  File "C:\Users\mat_i\AppData\Local\Programs\Python\Python313\Lib\site-packages\sqlalchemy\engine\create.py", line 643, in connect
    return dialect.connect(*cargs, **cparams)
           │       │        │        └ {'host': '34.176.19.140', 'database': 'motoagency', 'user': 'matiasciafardini', 'port': 3306, 'charset': 'utf8mb4', 'buffered...
           │       │        └ []
           │       └ <function DefaultDialect.connect at 0x000001A75B5A9800>
           └ <sqlalchemy.dialects.mysql.mysqlconnector.MySQLDialect_mysqlconnector object at 0x000001A75B9FEF90>
  File "C:\Users\mat_i\AppData\Local\Programs\Python\Python313\Lib\site-packages\sqlalchemy\engine\default.py", line 621, in connect
    return self.loaded_dbapi.connect(*cargs, **cparams)
           │    │            │        │        └ {'host': '34.176.19.140', 'database': 'motoagency', 'user': 'matiasciafardini', 'port': 3306, 'charset': 'utf8mb4', 'buffered...
           │    │            │        └ ()
           │    │            └ <function connect at 0x000001A75BE871A0>
           │    └ <module 'mysql.connector' from 'C:\\Users\\mat_i\\AppData\\Local\\Programs\\Python\\Python313\\Lib\\site-packages\\mysql\\con...
           └ <sqlalchemy.dialects.mysql.mysqlconnector.MySQLDialect_mysqlconnector object at 0x000001A75B9FEF90>
  File "C:\Users\mat_i\AppData\Local\Programs\Python\Python313\Lib\site-packages\mysql\connector\pooling.py", line 322, in connect
    return CMySQLConnection(*args, **kwargs)
           │                 │       └ {'host': '34.176.19.140', 'database': 'motoagency', 'user': 'matiasciafardini', 'port': 3306, 'charset': 'utf8mb4', 'buffered...
           │                 └ ()
           └ <class 'mysql.connector.connection_cext.CMySQLConnection'>
  File "C:\Users\mat_i\AppData\Local\Programs\Python\Python313\Lib\site-packages\mysql\connector\connection_cext.py", line 142, in __init__
    self.connect(**kwargs)
    │    │         └ {'host': '34.176.19.140', 'database': 'motoagency', 'user': 'matiasciafardini', 'port': 3306, 'charset': 'utf8mb4', 'buffered...
    │    └ <function MySQLConnectionAbstract.connect at 0x000001A75BADB2E0>
    └ <mysql.connector.connection_cext.CMySQLConnection object at 0x000001A75BEB5D30>
  File "C:\Users\mat_i\AppData\Local\Programs\Python\Python313\Lib\site-packages\mysql\connector\abstracts.py", line 1604, in connect
    self._open_connection()
    │    └ <function CMySQLConnection._open_connection at 0x000001A75BE634C0>
    └ <mysql.connector.connection_cext.CMySQLConnection object at 0x000001A75BEB5D30>
  File "C:\Users\mat_i\AppData\Local\Programs\Python\Python313\Lib\site-packages\mysql\connector\connection_cext.py", line 360, in _open_connection
    raise get_mysql_exception(
          └ <function get_mysql_exception at 0x000001A75BA604A0>

mysql.connector.errors.ProgrammingError: 1045 (28000): Access denied for user 'matiasciafardini'@'188.81.239.217' (using password: NO)


The above exception was the direct cause of the following exception:


Traceback (most recent call last):

  File "C:\Users\mat_i\OneDrive\Escritorio\App_gussoni\run.py", line 4, in <module>
    main()
    └ <function main at 0x000001A7590A5760>

  File "C:\Users\mat_i\OneDrive\Escritorio\App_gussoni\app\ui\main.py", line 11, in main
    win = MainWindow()
          └ <class 'app.ui.main_window.MainWindow'>

  File "C:\Users\mat_i\OneDrive\Escritorio\App_gussoni\app\ui\main_window.py", line 25, in __init__
    self.pageDashboard = DashboardPage(self)
    │                    │             └ <app.ui.main_window.MainWindow(0x1a75adee750, name="MainWindow") at 0x000001A7590C38C0>
    │                    └ <class 'app.ui.pages.dashboard_page.DashboardPage'>
    └ <app.ui.main_window.MainWindow(0x1a75adee750, name="MainWindow") at 0x000001A7590C38C0>

  File "C:\Users\mat_i\OneDrive\Escritorio\App_gussoni\app\ui\pages\dashboard_page.py", line 83, in __init__
    self.refresh_data()
    │    └ <function DashboardPage.refresh_data at 0x000001A75BEA2DE0>
    └ <app.ui.pages.dashboard_page.DashboardPage(0x1a75a6c1e60) at 0x000001A75BEDB700>

> File "C:\Users\mat_i\OneDrive\Escritorio\App_gussoni\app\ui\pages\dashboard_page.py", line 89, in refresh_data
    data: DashboardData = service.load_dashboard()
                          │       └ <function DashboardService.load_dashboard at 0x000001A75B927CE0>
                          └ <app.services.dashboard_service.DashboardService object at 0x000001A758FF67B0>

  File "C:\Users\mat_i\OneDrive\Escritorio\App_gussoni\app\services\dashboard_service.py", line 23, in load_dashboard
    ventas_mes = self.ventas_repo.metrics_mes_actual()
                 │    │           └ <function VentasRepository.metrics_mes_actual at 0x000001A75B927920>
                 │    └ <app.repositories.ventas_repository.VentasRepository object at 0x000001A7590AC1A0>
                 └ <app.services.dashboard_service.DashboardService object at 0x000001A758FF67B0>

  File "C:\Users\mat_i\OneDrive\Escritorio\App_gussoni\app\repositories\ventas_repository.py", line 16, in metrics_mes_actual
    row = self.db.execute(text("""
          │    │  │       └ <function text at 0x000001A75B444EA0>
          │    │  └ <function Session.execute at 0x000001A75B853A60>
          │    └ <sqlalchemy.orm.session.Session object at 0x000001A758FF6A50>
          └ <app.repositories.ventas_repository.VentasRepository object at 0x000001A7590AC1A0>

  File "C:\Users\mat_i\AppData\Local\Programs\Python\Python313\Lib\site-packages\sqlalchemy\orm\session.py", line 2362, in execute
    return self._execute_internal(
           │    └ <function Session._execute_internal at 0x000001A75B853740>
           └ <sqlalchemy.orm.session.Session object at 0x000001A758FF6A50>
  File "C:\Users\mat_i\AppData\Local\Programs\Python\Python313\Lib\site-packages\sqlalchemy\orm\session.py", line 2237, in _execute_internal
    conn = self._connection_for_bind(bind)
           │    │                    └ Engine(mysql+mysqlconnector://matiasciafardini:***@34.176.19.140:3306/motoagency?charset=utf8mb4)
           │    └ <function Session._connection_for_bind at 0x000001A75B8534C0>
           └ <sqlalchemy.orm.session.Session object at 0x000001A758FF6A50>
  File "C:\Users\mat_i\AppData\Local\Programs\Python\Python313\Lib\site-packages\sqlalchemy\orm\session.py", line 2106, in _connection_for_bind
    return trans._connection_for_bind(engine, execution_options)
           │     │                    │       └ None
           │     │                    └ Engine(mysql+mysqlconnector://matiasciafardini:***@34.176.19.140:3306/motoagency?charset=utf8mb4)
           │     └ <function SessionTransaction._connection_for_bind at 0x000001A75B851E40>
           └ <sqlalchemy.orm.session.SessionTransaction object at 0x000001A75B77A890>
  File "<string>", line 2, in _connection_for_bind
  File "C:\Users\mat_i\AppData\Local\Programs\Python\Python313\Lib\site-packages\sqlalchemy\orm\state_changes.py", line 139, in _go
    ret_value = fn(self, *arg, **kw)
                │  │      │      └ {}
                │  │      └ (Engine(mysql+mysqlconnector://matiasciafardini:***@34.176.19.140:3306/motoagency?charset=utf8mb4), None)
                │  └ <sqlalchemy.orm.session.SessionTransaction object at 0x000001A75B77A890>
                └ <function SessionTransaction._connection_for_bind at 0x000001A75B851DA0>
  File "C:\Users\mat_i\AppData\Local\Programs\Python\Python313\Lib\site-packages\sqlalchemy\orm\session.py", line 1189, in _connection_for_bind
    conn = bind.connect()
           │    └ <function Engine.connect at 0x000001A75B49E2A0>
           └ Engine(mysql+mysqlconnector://matiasciafardini:***@34.176.19.140:3306/motoagency?charset=utf8mb4)
  File "C:\Users\mat_i\AppData\Local\Programs\Python\Python313\Lib\site-packages\sqlalchemy\engine\base.py", line 3278, in connect
    return self._connection_cls(self)
           │    │               └ Engine(mysql+mysqlconnector://matiasciafardini:***@34.176.19.140:3306/motoagency?charset=utf8mb4)
           │    └ <class 'sqlalchemy.engine.base.Connection'>
           └ Engine(mysql+mysqlconnector://matiasciafardini:***@34.176.19.140:3306/motoagency?charset=utf8mb4)
  File "C:\Users\mat_i\AppData\Local\Programs\Python\Python313\Lib\site-packages\sqlalchemy\engine\base.py", line 148, in __init__
    Connection._handle_dbapi_exception_noconnection(
    │          └ <classmethod(<function Connection._handle_dbapi_exception_noconnection at 0x000001A75B497B00>)>
    └ <class 'sqlalchemy.engine.base.Connection'>
  File "C:\Users\mat_i\AppData\Local\Programs\Python\Python313\Lib\site-packages\sqlalchemy\engine\base.py", line 2442, in _handle_dbapi_exception_noconnection
    raise sqlalchemy_exception.with_traceback(exc_info[2]) from e
          │                    │              │                 └ ProgrammingError(1045, "1045 (28000): Access denied for user 'matiasciafardini'@'188.81.239.217' (using password: NO)", '28000')
          │                    │              └ (<class 'mysql.connector.errors.ProgrammingError'>, ProgrammingError(1045, "1045 (28000): Access denied for user 'matiasciafa...
          │                    └ <method 'with_traceback' of 'BaseException' objects>
          └ ProgrammingError("(mysql.connector.errors.ProgrammingError) 1045 (28000): Access denied for user 'matiasciafardini'@'188.81.2...
  File "C:\Users\mat_i\AppData\Local\Programs\Python\Python313\Lib\site-packages\sqlalchemy\engine\base.py", line 146, in __init__
    self._dbapi_connection = engine.raw_connection()
    │                        │      └ <function Engine.raw_connection at 0x000001A75B49E340>
    │                        └ Engine(mysql+mysqlconnector://matiasciafardini:***@34.176.19.140:3306/motoagency?charset=utf8mb4)
    └ <sqlalchemy.engine.base.Connection object at 0x000001A75BEB5BE0>
  File "C:\Users\mat_i\AppData\Local\Programs\Python\Python313\Lib\site-packages\sqlalchemy\engine\base.py", line 3302, in raw_connection
    return self.pool.connect()
           │    │    └ <function Pool.connect at 0x000001A75B037240>
           │    └ <sqlalchemy.pool.impl.QueuePool object at 0x000001A75B9FF380>
           └ Engine(mysql+mysqlconnector://matiasciafardini:***@34.176.19.140:3306/motoagency?charset=utf8mb4)
  File "C:\Users\mat_i\AppData\Local\Programs\Python\Python313\Lib\site-packages\sqlalchemy\pool\base.py", line 449, in connect
    return _ConnectionFairy._checkout(self)
           │                │         └ <sqlalchemy.pool.impl.QueuePool object at 0x000001A75B9FF380>
           │                └ <classmethod(<function _ConnectionFairy._checkout at 0x000001A75B0693A0>)>
           └ <class 'sqlalchemy.pool.base._ConnectionFairy'>
  File "C:\Users\mat_i\AppData\Local\Programs\Python\Python313\Lib\site-packages\sqlalchemy\pool\base.py", line 1263, in _checkout
    fairy = _ConnectionRecord.checkout(pool)
            │                 │        └ <sqlalchemy.pool.impl.QueuePool object at 0x000001A75B9FF380>
            │                 └ <classmethod(<function _ConnectionRecord.checkout at 0x000001A75B037EC0>)>
            └ <class 'sqlalchemy.pool.base._ConnectionRecord'>
  File "C:\Users\mat_i\AppData\Local\Programs\Python\Python313\Lib\site-packages\sqlalchemy\pool\base.py", line 712, in checkout
    rec = pool._do_get()
          │    └ <function QueuePool._do_get at 0x000001A75B06B1A0>
          └ <sqlalchemy.pool.impl.QueuePool object at 0x000001A75B9FF380>
  File "C:\Users\mat_i\AppData\Local\Programs\Python\Python313\Lib\site-packages\sqlalchemy\pool\impl.py", line 179, in _do_get
    with util.safe_reraise():
         │    └ <class 'sqlalchemy.util.langhelpers.safe_reraise'>
         └ <module 'sqlalchemy.util' from 'C:\\Users\\mat_i\\AppData\\Local\\Programs\\Python\\Python313\\Lib\\site-packages\\sqlalchemy...
  File "C:\Users\mat_i\AppData\Local\Programs\Python\Python313\Lib\site-packages\sqlalchemy\util\langhelpers.py", line 146, in __exit__
    raise exc_value.with_traceback(exc_tb)
          │         │              └ <traceback object at 0x000001A75BEF6440>
          │         └ <method 'with_traceback' of 'BaseException' objects>
          └ ProgrammingError(1045, "1045 (28000): Access denied for user 'matiasciafardini'@'188.81.239.217' (using password: NO)", '28000')
  File "C:\Users\mat_i\AppData\Local\Programs\Python\Python313\Lib\site-packages\sqlalchemy\pool\impl.py", line 177, in _do_get
    return self._create_connection()
           │    └ <function Pool._create_connection at 0x000001A75B036FC0>
           └ <sqlalchemy.pool.impl.QueuePool object at 0x000001A75B9FF380>
  File "C:\Users\mat_i\AppData\Local\Programs\Python\Python313\Lib\site-packages\sqlalchemy\pool\base.py", line 390, in _create_connection
    return _ConnectionRecord(self)
           │                 └ <sqlalchemy.pool.impl.QueuePool object at 0x000001A75B9FF380>
           └ <class 'sqlalchemy.pool.base._ConnectionRecord'>
  File "C:\Users\mat_i\AppData\Local\Programs\Python\Python313\Lib\site-packages\sqlalchemy\pool\base.py", line 674, in __init__
    self.__connect()
    └ <sqlalchemy.pool.base._ConnectionRecord object at 0x000001A757A46E70>
  File "C:\Users\mat_i\AppData\Local\Programs\Python\Python313\Lib\site-packages\sqlalchemy\pool\base.py", line 900, in __connect
    with util.safe_reraise():
         │    └ <class 'sqlalchemy.util.langhelpers.safe_reraise'>
         └ <module 'sqlalchemy.util' from 'C:\\Users\\mat_i\\AppData\\Local\\Programs\\Python\\Python313\\Lib\\site-packages\\sqlalchemy...
  File "C:\Users\mat_i\AppData\Local\Programs\Python\Python313\Lib\site-packages\sqlalchemy\util\langhelpers.py", line 146, in __exit__
    raise exc_value.with_traceback(exc_tb)
          │         │              └ <traceback object at 0x000001A75BEF5D40>
          │         └ <method 'with_traceback' of 'BaseException' objects>
          └ ProgrammingError(1045, "1045 (28000): Access denied for user 'matiasciafardini'@'188.81.239.217' (using password: NO)", '28000')
  File "C:\Users\mat_i\AppData\Local\Programs\Python\Python313\Lib\site-packages\sqlalchemy\pool\base.py", line 896, in __connect
    self.dbapi_connection = connection = pool._invoke_creator(self)
    │    │                               │    │               └ <sqlalchemy.pool.base._ConnectionRecord object at 0x000001A757A46E70>
    │    │                               │    └ <function create_engine.<locals>.connect at 0x000001A75B9385E0>
    │    │                               └ <sqlalchemy.pool.impl.QueuePool object at 0x000001A75B9FF380>
    │    └ <member 'dbapi_connection' of '_ConnectionRecord' objects>
    └ <sqlalchemy.pool.base._ConnectionRecord object at 0x000001A757A46E70>
  File "C:\Users\mat_i\AppData\Local\Programs\Python\Python313\Lib\site-packages\sqlalchemy\engine\create.py", line 643, in connect
    return dialect.connect(*cargs, **cparams)
           │       │        │        └ {'host': '34.176.19.140', 'database': 'motoagency', 'user': 'matiasciafardini', 'port': 3306, 'charset': 'utf8mb4', 'buffered...
           │       │        └ []
           │       └ <function DefaultDialect.connect at 0x000001A75B5A9800>
           └ <sqlalchemy.dialects.mysql.mysqlconnector.MySQLDialect_mysqlconnector object at 0x000001A75B9FEF90>
  File "C:\Users\mat_i\AppData\Local\Programs\Python\Python313\Lib\site-packages\sqlalchemy\engine\default.py", line 621, in connect
    return self.loaded_dbapi.connect(*cargs, **cparams)
           │    │            │        │        └ {'host': '34.176.19.140', 'database': 'motoagency', 'user': 'matiasciafardini', 'port': 3306, 'charset': 'utf8mb4', 'buffered...
           │    │            │        └ ()
           │    │            └ <function connect at 0x000001A75BE871A0>
           │    └ <module 'mysql.connector' from 'C:\\Users\\mat_i\\AppData\\Local\\Programs\\Python\\Python313\\Lib\\site-packages\\mysql\\con...
           └ <sqlalchemy.dialects.mysql.mysqlconnector.MySQLDialect_mysqlconnector object at 0x000001A75B9FEF90>
  File "C:\Users\mat_i\AppData\Local\Programs\Python\Python313\Lib\site-packages\mysql\connector\pooling.py", line 322, in connect
    return CMySQLConnection(*args, **kwargs)
           │                 │       └ {'host': '34.176.19.140', 'database': 'motoagency', 'user': 'matiasciafardini', 'port': 3306, 'charset': 'utf8mb4', 'buffered...
           │                 └ ()
           └ <class 'mysql.connector.connection_cext.CMySQLConnection'>
  File "C:\Users\mat_i\AppData\Local\Programs\Python\Python313\Lib\site-packages\mysql\connector\connection_cext.py", line 142, in __init__
    self.connect(**kwargs)
    │    │         └ {'host': '34.176.19.140', 'database': 'motoagency', 'user': 'matiasciafardini', 'port': 3306, 'charset': 'utf8mb4', 'buffered...
    │    └ <function MySQLConnectionAbstract.connect at 0x000001A75BADB2E0>
    └ <mysql.connector.connection_cext.CMySQLConnection object at 0x000001A75BEB5D30>
  File "C:\Users\mat_i\AppData\Local\Programs\Python\Python313\Lib\site-packages\mysql\connector\abstracts.py", line 1604, in connect
    self._open_connection()
    │    └ <function CMySQLConnection._open_connection at 0x000001A75BE634C0>
    └ <mysql.connector.connection_cext.CMySQLConnection object at 0x000001A75BEB5D30>
  File "C:\Users\mat_i\AppData\Local\Programs\Python\Python313\Lib\site-packages\mysql\connector\connection_cext.py", line 360, in _open_connection
    raise get_mysql_exception(
          └ <function get_mysql_exception at 0x000001A75BA604A0>

sqlalchemy.exc.ProgrammingError: (mysql.connector.errors.ProgrammingError) 1045 (28000): Access denied for user 'matiasciafardini'@'188.81.239.217' (using password: NO)
(Background on this error at: https://sqlalche.me/e/20/f405)
2025-10-10 04:02:14.221 | ERROR    | app.ui.pages.dashboard_page:refresh_data:91 - No se pudo cargar dashboard: (mysql.connector.errors.ProgrammingError) 1045 (28000): Access denied for user 'matiasciafardini'@'188.81.239.217' (using password: NO)
(Background on this error at: https://sqlalche.me/e/20/f405)
Traceback (most recent call last):

  File "C:\Users\mat_i\AppData\Local\Programs\Python\Python313\Lib\site-packages\mysql\connector\connection_cext.py", line 354, in _open_connection
    self._cmysql.connect(**cnx_kwargs)
    │    │       │         └ {'host': '34.176.19.140', 'user': 'matiasciafardini', 'password': '', 'password1': '', 'password2': '', 'password3': '', 'dat...
    │    │       └ <method 'connect' of '_mysql_connector.MySQL' objects>
    │    └ <_mysql_connector.MySQL object at 0x000001B6795FCD80>
    └ <mysql.connector.connection_cext.CMySQLConnection object at 0x000001B67B497A10>

_mysql_connector.MySQLInterfaceError: Access denied for user 'matiasciafardini'@'188.81.239.217' (using password: NO)


The above exception was the direct cause of the following exception:


Traceback (most recent call last):

  File "C:\Users\mat_i\AppData\Local\Programs\Python\Python313\Lib\site-packages\sqlalchemy\engine\base.py", line 146, in __init__
    self._dbapi_connection = engine.raw_connection()
    │                        │      └ <function Engine.raw_connection at 0x000001B679E46E80>
    │                        └ Engine(mysql+mysqlconnector://matiasciafardini:***@34.176.19.140:3306/motoagency?charset=utf8mb4)
    └ <sqlalchemy.engine.base.Connection object at 0x000001B67B4978C0>
  File "C:\Users\mat_i\AppData\Local\Programs\Python\Python313\Lib\site-packages\sqlalchemy\engine\base.py", line 3302, in raw_connection
    return self.pool.connect()
           │    │    └ <function Pool.connect at 0x000001B6799DFD80>
           │    └ <sqlalchemy.pool.impl.QueuePool object at 0x000001B67B494D70>
           └ Engine(mysql+mysqlconnector://matiasciafardini:***@34.176.19.140:3306/motoagency?charset=utf8mb4)
  File "C:\Users\mat_i\AppData\Local\Programs\Python\Python313\Lib\site-packages\sqlalchemy\pool\base.py", line 449, in connect
    return _ConnectionFairy._checkout(self)
           │                │         └ <sqlalchemy.pool.impl.QueuePool object at 0x000001B67B494D70>
           │                └ <classmethod(<function _ConnectionFairy._checkout at 0x000001B679A09EE0>)>
           └ <class 'sqlalchemy.pool.base._ConnectionFairy'>
  File "C:\Users\mat_i\AppData\Local\Programs\Python\Python313\Lib\site-packages\sqlalchemy\pool\base.py", line 1263, in _checkout
    fairy = _ConnectionRecord.checkout(pool)
            │                 │        └ <sqlalchemy.pool.impl.QueuePool object at 0x000001B67B494D70>
            │                 └ <classmethod(<function _ConnectionRecord.checkout at 0x000001B679A08A40>)>
            └ <class 'sqlalchemy.pool.base._ConnectionRecord'>
  File "C:\Users\mat_i\AppData\Local\Programs\Python\Python313\Lib\site-packages\sqlalchemy\pool\base.py", line 712, in checkout
    rec = pool._do_get()
          │    └ <function QueuePool._do_get at 0x000001B679A0BCE0>
          └ <sqlalchemy.pool.impl.QueuePool object at 0x000001B67B494D70>
  File "C:\Users\mat_i\AppData\Local\Programs\Python\Python313\Lib\site-packages\sqlalchemy\pool\impl.py", line 179, in _do_get
    with util.safe_reraise():
         │    └ <class 'sqlalchemy.util.langhelpers.safe_reraise'>
         └ <module 'sqlalchemy.util' from 'C:\\Users\\mat_i\\AppData\\Local\\Programs\\Python\\Python313\\Lib\\site-packages\\sqlalchemy...
  File "C:\Users\mat_i\AppData\Local\Programs\Python\Python313\Lib\site-packages\sqlalchemy\util\langhelpers.py", line 146, in __exit__
    raise exc_value.with_traceback(exc_tb)
          │         │              └ <traceback object at 0x000001B67B529940>
          │         └ <method 'with_traceback' of 'BaseException' objects>
          └ ProgrammingError(1045, "1045 (28000): Access denied for user 'matiasciafardini'@'188.81.239.217' (using password: NO)", '28000')
  File "C:\Users\mat_i\AppData\Local\Programs\Python\Python313\Lib\site-packages\sqlalchemy\pool\impl.py", line 177, in _do_get
    return self._create_connection()
           │    └ <function Pool._create_connection at 0x000001B6799DFB00>
           └ <sqlalchemy.pool.impl.QueuePool object at 0x000001B67B494D70>
  File "C:\Users\mat_i\AppData\Local\Programs\Python\Python313\Lib\site-packages\sqlalchemy\pool\base.py", line 390, in _create_connection
    return _ConnectionRecord(self)
           │                 └ <sqlalchemy.pool.impl.QueuePool object at 0x000001B67B494D70>
           └ <class 'sqlalchemy.pool.base._ConnectionRecord'>
  File "C:\Users\mat_i\AppData\Local\Programs\Python\Python313\Lib\site-packages\sqlalchemy\pool\base.py", line 674, in __init__
    self.__connect()
    └ <sqlalchemy.pool.base._ConnectionRecord object at 0x000001B676436E70>
  File "C:\Users\mat_i\AppData\Local\Programs\Python\Python313\Lib\site-packages\sqlalchemy\pool\base.py", line 900, in __connect
    with util.safe_reraise():
         │    └ <class 'sqlalchemy.util.langhelpers.safe_reraise'>
         └ <module 'sqlalchemy.util' from 'C:\\Users\\mat_i\\AppData\\Local\\Programs\\Python\\Python313\\Lib\\site-packages\\sqlalchemy...
  File "C:\Users\mat_i\AppData\Local\Programs\Python\Python313\Lib\site-packages\sqlalchemy\util\langhelpers.py", line 146, in __exit__
    raise exc_value.with_traceback(exc_tb)
          │         │              └ <traceback object at 0x000001B67B529180>
          │         └ <method 'with_traceback' of 'BaseException' objects>
          └ ProgrammingError(1045, "1045 (28000): Access denied for user 'matiasciafardini'@'188.81.239.217' (using password: NO)", '28000')
  File "C:\Users\mat_i\AppData\Local\Programs\Python\Python313\Lib\site-packages\sqlalchemy\pool\base.py", line 896, in __connect
    self.dbapi_connection = connection = pool._invoke_creator(self)
    │    │                               │    │               └ <sqlalchemy.pool.base._ConnectionRecord object at 0x000001B676436E70>
    │    │                               │    └ <function create_engine.<locals>.connect at 0x000001B67A2D4180>
    │    │                               └ <sqlalchemy.pool.impl.QueuePool object at 0x000001B67B494D70>
    │    └ <member 'dbapi_connection' of '_ConnectionRecord' objects>
    └ <sqlalchemy.pool.base._ConnectionRecord object at 0x000001B676436E70>
  File "C:\Users\mat_i\AppData\Local\Programs\Python\Python313\Lib\site-packages\sqlalchemy\engine\create.py", line 643, in connect
    return dialect.connect(*cargs, **cparams)
           │       │        │        └ {'host': '34.176.19.140', 'database': 'motoagency', 'user': 'matiasciafardini', 'port': 3306, 'charset': 'utf8mb4', 'buffered...
           │       │        └ []
           │       └ <function DefaultDialect.connect at 0x000001B679F22340>
           └ <sqlalchemy.dialects.mysql.mysqlconnector.MySQLDialect_mysqlconnector object at 0x000001B67B494980>
  File "C:\Users\mat_i\AppData\Local\Programs\Python\Python313\Lib\site-packages\sqlalchemy\engine\default.py", line 621, in connect
    return self.loaded_dbapi.connect(*cargs, **cparams)
           │    │            │        │        └ {'host': '34.176.19.140', 'database': 'motoagency', 'user': 'matiasciafardini', 'port': 3306, 'charset': 'utf8mb4', 'buffered...
           │    │            │        └ ()
           │    │            └ <function connect at 0x000001B67B4B6E80>
           │    └ <module 'mysql.connector' from 'C:\\Users\\mat_i\\AppData\\Local\\Programs\\Python\\Python313\\Lib\\site-packages\\mysql\\con...
           └ <sqlalchemy.dialects.mysql.mysqlconnector.MySQLDialect_mysqlconnector object at 0x000001B67B494980>
  File "C:\Users\mat_i\AppData\Local\Programs\Python\Python313\Lib\site-packages\mysql\connector\pooling.py", line 322, in connect
    return CMySQLConnection(*args, **kwargs)
           │                 │       └ {'host': '34.176.19.140', 'database': 'motoagency', 'user': 'matiasciafardini', 'port': 3306, 'charset': 'utf8mb4', 'buffered...
           │                 └ ()
           └ <class 'mysql.connector.connection_cext.CMySQLConnection'>
  File "C:\Users\mat_i\AppData\Local\Programs\Python\Python313\Lib\site-packages\mysql\connector\connection_cext.py", line 142, in __init__
    self.connect(**kwargs)
    │    │         └ {'host': '34.176.19.140', 'database': 'motoagency', 'user': 'matiasciafardini', 'port': 3306, 'charset': 'utf8mb4', 'buffered...
    │    └ <function MySQLConnectionAbstract.connect at 0x000001B67A442FC0>
    └ <mysql.connector.connection_cext.CMySQLConnection object at 0x000001B67B497A10>
  File "C:\Users\mat_i\AppData\Local\Programs\Python\Python313\Lib\site-packages\mysql\connector\abstracts.py", line 1604, in connect
    self._open_connection()
    │    └ <function CMySQLConnection._open_connection at 0x000001B67B48B1A0>
    └ <mysql.connector.connection_cext.CMySQLConnection object at 0x000001B67B497A10>
  File "C:\Users\mat_i\AppData\Local\Programs\Python\Python313\Lib\site-packages\mysql\connector\connection_cext.py", line 360, in _open_connection
    raise get_mysql_exception(
          └ <function get_mysql_exception at 0x000001B67A3F8180>

mysql.connector.errors.ProgrammingError: 1045 (28000): Access denied for user 'matiasciafardini'@'188.81.239.217' (using password: NO)


The above exception was the direct cause of the following exception:


Traceback (most recent call last):

  File "C:\Users\mat_i\OneDrive\Escritorio\App_gussoni\run.py", line 4, in <module>
    main()
    └ <function main at 0x000001B678EF5760>

  File "C:\Users\mat_i\OneDrive\Escritorio\App_gussoni\app\ui\main.py", line 11, in main
    win = MainWindow()
          └ <class 'app.ui.main_window.MainWindow'>

  File "C:\Users\mat_i\OneDrive\Escritorio\App_gussoni\app\ui\main_window.py", line 26, in __init__
    self.pageDashboard = DashboardPage(self)
    │                    │             └ <app.ui.main_window.MainWindow(0x1b679082c50, name="MainWindow") at 0x000001B679C389C0>
    │                    └ <class 'app.ui.pages.dashboard_page.DashboardPage'>
    └ <app.ui.main_window.MainWindow(0x1b679082c50, name="MainWindow") at 0x000001B679C389C0>

  File "C:\Users\mat_i\OneDrive\Escritorio\App_gussoni\app\ui\pages\dashboard_page.py", line 83, in __init__
    self.refresh_data()
    │    └ <function DashboardPage.refresh_data at 0x000001B67B4E4400>
    └ <app.ui.pages.dashboard_page.DashboardPage(0x1b679081390) at 0x000001B67B50ED00>

> File "C:\Users\mat_i\OneDrive\Escritorio\App_gussoni\app\ui\pages\dashboard_page.py", line 89, in refresh_data
    data: DashboardData = service.load_dashboard()
                          │       └ <function DashboardService.load_dashboard at 0x000001B67B4E4040>
                          └ <app.services.dashboard_service.DashboardService object at 0x000001B678E467B0>

  File "C:\Users\mat_i\OneDrive\Escritorio\App_gussoni\app\services\dashboard_service.py", line 23, in load_dashboard
    ventas_mes = self.ventas_repo.metrics_mes_actual()
                 │    │           └ <function VentasRepository.metrics_mes_actual at 0x000001B67B4CFBA0>
                 │    └ <app.repositories.ventas_repository.VentasRepository object at 0x000001B67B4974D0>
                 └ <app.services.dashboard_service.DashboardService object at 0x000001B678E467B0>

  File "C:\Users\mat_i\OneDrive\Escritorio\App_gussoni\app\repositories\ventas_repository.py", line 16, in metrics_mes_actual
    row = self.db.execute(text("""
          │    │  │       └ <function text at 0x000001B679DDD9E0>
          │    │  └ <function Session.execute at 0x000001B67A1F8680>
          │    └ <sqlalchemy.orm.session.Session object at 0x000001B678E46A50>
          └ <app.repositories.ventas_repository.VentasRepository object at 0x000001B67B4974D0>

  File "C:\Users\mat_i\AppData\Local\Programs\Python\Python313\Lib\site-packages\sqlalchemy\orm\session.py", line 2362, in execute
    return self._execute_internal(
           │    └ <function Session._execute_internal at 0x000001B67A1F8360>
           └ <sqlalchemy.orm.session.Session object at 0x000001B678E46A50>
  File "C:\Users\mat_i\AppData\Local\Programs\Python\Python313\Lib\site-packages\sqlalchemy\orm\session.py", line 2237, in _execute_internal
    conn = self._connection_for_bind(bind)
           │    │                    └ Engine(mysql+mysqlconnector://matiasciafardini:***@34.176.19.140:3306/motoagency?charset=utf8mb4)
           │    └ <function Session._connection_for_bind at 0x000001B67A1F80E0>
           └ <sqlalchemy.orm.session.Session object at 0x000001B678E46A50>
  File "C:\Users\mat_i\AppData\Local\Programs\Python\Python313\Lib\site-packages\sqlalchemy\orm\session.py", line 2106, in _connection_for_bind
    return trans._connection_for_bind(engine, execution_options)
           │     │                    │       └ None
           │     │                    └ Engine(mysql+mysqlconnector://matiasciafardini:***@34.176.19.140:3306/motoagency?charset=utf8mb4)
           │     └ <function SessionTransaction._connection_for_bind at 0x000001B67A1EAA20>
           └ <sqlalchemy.orm.session.SessionTransaction object at 0x000001B67A21F450>
  File "<string>", line 2, in _connection_for_bind
  File "C:\Users\mat_i\AppData\Local\Programs\Python\Python313\Lib\site-packages\sqlalchemy\orm\state_changes.py", line 139, in _go
    ret_value = fn(self, *arg, **kw)
                │  │      │      └ {}
                │  │      └ (Engine(mysql+mysqlconnector://matiasciafardini:***@34.176.19.140:3306/motoagency?charset=utf8mb4), None)
                │  └ <sqlalchemy.orm.session.SessionTransaction object at 0x000001B67A21F450>
                └ <function SessionTransaction._connection_for_bind at 0x000001B67A1EA980>
  File "C:\Users\mat_i\AppData\Local\Programs\Python\Python313\Lib\site-packages\sqlalchemy\orm\session.py", line 1189, in _connection_for_bind
    conn = bind.connect()
           │    └ <function Engine.connect at 0x000001B679E46DE0>
           └ Engine(mysql+mysqlconnector://matiasciafardini:***@34.176.19.140:3306/motoagency?charset=utf8mb4)
  File "C:\Users\mat_i\AppData\Local\Programs\Python\Python313\Lib\site-packages\sqlalchemy\engine\base.py", line 3278, in connect
    return self._connection_cls(self)
           │    │               └ Engine(mysql+mysqlconnector://matiasciafardini:***@34.176.19.140:3306/motoagency?charset=utf8mb4)
           │    └ <class 'sqlalchemy.engine.base.Connection'>
           └ Engine(mysql+mysqlconnector://matiasciafardini:***@34.176.19.140:3306/motoagency?charset=utf8mb4)
  File "C:\Users\mat_i\AppData\Local\Programs\Python\Python313\Lib\site-packages\sqlalchemy\engine\base.py", line 148, in __init__
    Connection._handle_dbapi_exception_noconnection(
    │          └ <classmethod(<function Connection._handle_dbapi_exception_noconnection at 0x000001B679E44680>)>
    └ <class 'sqlalchemy.engine.base.Connection'>
  File "C:\Users\mat_i\AppData\Local\Programs\Python\Python313\Lib\site-packages\sqlalchemy\engine\base.py", line 2442, in _handle_dbapi_exception_noconnection
    raise sqlalchemy_exception.with_traceback(exc_info[2]) from e
          │                    │              │                 └ ProgrammingError(1045, "1045 (28000): Access denied for user 'matiasciafardini'@'188.81.239.217' (using password: NO)", '28000')
          │                    │              └ (<class 'mysql.connector.errors.ProgrammingError'>, ProgrammingError(1045, "1045 (28000): Access denied for user 'matiasciafa...
          │                    └ <method 'with_traceback' of 'BaseException' objects>
          └ ProgrammingError("(mysql.connector.errors.ProgrammingError) 1045 (28000): Access denied for user 'matiasciafardini'@'188.81.2...
  File "C:\Users\mat_i\AppData\Local\Programs\Python\Python313\Lib\site-packages\sqlalchemy\engine\base.py", line 146, in __init__
    self._dbapi_connection = engine.raw_connection()
    │                        │      └ <function Engine.raw_connection at 0x000001B679E46E80>
    │                        └ Engine(mysql+mysqlconnector://matiasciafardini:***@34.176.19.140:3306/motoagency?charset=utf8mb4)
    └ <sqlalchemy.engine.base.Connection object at 0x000001B67B4978C0>
  File "C:\Users\mat_i\AppData\Local\Programs\Python\Python313\Lib\site-packages\sqlalchemy\engine\base.py", line 3302, in raw_connection
    return self.pool.connect()
           │    │    └ <function Pool.connect at 0x000001B6799DFD80>
           │    └ <sqlalchemy.pool.impl.QueuePool object at 0x000001B67B494D70>
           └ Engine(mysql+mysqlconnector://matiasciafardini:***@34.176.19.140:3306/motoagency?charset=utf8mb4)
  File "C:\Users\mat_i\AppData\Local\Programs\Python\Python313\Lib\site-packages\sqlalchemy\pool\base.py", line 449, in connect
    return _ConnectionFairy._checkout(self)
           │                │         └ <sqlalchemy.pool.impl.QueuePool object at 0x000001B67B494D70>
           │                └ <classmethod(<function _ConnectionFairy._checkout at 0x000001B679A09EE0>)>
           └ <class 'sqlalchemy.pool.base._ConnectionFairy'>
  File "C:\Users\mat_i\AppData\Local\Programs\Python\Python313\Lib\site-packages\sqlalchemy\pool\base.py", line 1263, in _checkout
    fairy = _ConnectionRecord.checkout(pool)
            │                 │        └ <sqlalchemy.pool.impl.QueuePool object at 0x000001B67B494D70>
            │                 └ <classmethod(<function _ConnectionRecord.checkout at 0x000001B679A08A40>)>
            └ <class 'sqlalchemy.pool.base._ConnectionRecord'>
  File "C:\Users\mat_i\AppData\Local\Programs\Python\Python313\Lib\site-packages\sqlalchemy\pool\base.py", line 712, in checkout
    rec = pool._do_get()
          │    └ <function QueuePool._do_get at 0x000001B679A0BCE0>
          └ <sqlalchemy.pool.impl.QueuePool object at 0x000001B67B494D70>
  File "C:\Users\mat_i\AppData\Local\Programs\Python\Python313\Lib\site-packages\sqlalchemy\pool\impl.py", line 179, in _do_get
    with util.safe_reraise():
         │    └ <class 'sqlalchemy.util.langhelpers.safe_reraise'>
         └ <module 'sqlalchemy.util' from 'C:\\Users\\mat_i\\AppData\\Local\\Programs\\Python\\Python313\\Lib\\site-packages\\sqlalchemy...
  File "C:\Users\mat_i\AppData\Local\Programs\Python\Python313\Lib\site-packages\sqlalchemy\util\langhelpers.py", line 146, in __exit__
    raise exc_value.with_traceback(exc_tb)
          │         │              └ <traceback object at 0x000001B67B529940>
          │         └ <method 'with_traceback' of 'BaseException' objects>
          └ ProgrammingError(1045, "1045 (28000): Access denied for user 'matiasciafardini'@'188.81.239.217' (using password: NO)", '28000')
  File "C:\Users\mat_i\AppData\Local\Programs\Python\Python313\Lib\site-packages\sqlalchemy\pool\impl.py", line 177, in _do_get
    return self._create_connection()
           │    └ <function Pool._create_connection at 0x000001B6799DFB00>
           └ <sqlalchemy.pool.impl.QueuePool object at 0x000001B67B494D70>
  File "C:\Users\mat_i\AppData\Local\Programs\Python\Python313\Lib\site-packages\sqlalchemy\pool\base.py", line 390, in _create_connection
    return _ConnectionRecord(self)
           │                 └ <sqlalchemy.pool.impl.QueuePool object at 0x000001B67B494D70>
           └ <class 'sqlalchemy.pool.base._ConnectionRecord'>
  File "C:\Users\mat_i\AppData\Local\Programs\Python\Python313\Lib\site-packages\sqlalchemy\pool\base.py", line 674, in __init__
    self.__connect()
    └ <sqlalchemy.pool.base._ConnectionRecord object at 0x000001B676436E70>
  File "C:\Users\mat_i\AppData\Local\Programs\Python\Python313\Lib\site-packages\sqlalchemy\pool\base.py", line 900, in __connect
    with util.safe_reraise():
         │    └ <class 'sqlalchemy.util.langhelpers.safe_reraise'>
         └ <module 'sqlalchemy.util' from 'C:\\Users\\mat_i\\AppData\\Local\\Programs\\Python\\Python313\\Lib\\site-packages\\sqlalchemy...
  File "C:\Users\mat_i\AppData\Local\Programs\Python\Python313\Lib\site-packages\sqlalchemy\util\langhelpers.py", line 146, in __exit__
    raise exc_value.with_traceback(exc_tb)
          │         │              └ <traceback object at 0x000001B67B529180>
          │         └ <method 'with_traceback' of 'BaseException' objects>
          └ ProgrammingError(1045, "1045 (28000): Access denied for user 'matiasciafardini'@'188.81.239.217' (using password: NO)", '28000')
  File "C:\Users\mat_i\AppData\Local\Programs\Python\Python313\Lib\site-packages\sqlalchemy\pool\base.py", line 896, in __connect
    self.dbapi_connection = connection = pool._invoke_creator(self)
    │    │                               │    │               └ <sqlalchemy.pool.base._ConnectionRecord object at 0x000001B676436E70>
    │    │                               │    └ <function create_engine.<locals>.connect at 0x000001B67A2D4180>
    │    │                               └ <sqlalchemy.pool.impl.QueuePool object at 0x000001B67B494D70>
    │    └ <member 'dbapi_connection' of '_ConnectionRecord' objects>
    └ <sqlalchemy.pool.base._ConnectionRecord object at 0x000001B676436E70>
  File "C:\Users\mat_i\AppData\Local\Programs\Python\Python313\Lib\site-packages\sqlalchemy\engine\create.py", line 643, in connect
    return dialect.connect(*cargs, **cparams)
           │       │        │        └ {'host': '34.176.19.140', 'database': 'motoagency', 'user': 'matiasciafardini', 'port': 3306, 'charset': 'utf8mb4', 'buffered...
           │       │        └ []
           │       └ <function DefaultDialect.connect at 0x000001B679F22340>
           └ <sqlalchemy.dialects.mysql.mysqlconnector.MySQLDialect_mysqlconnector object at 0x000001B67B494980>
  File "C:\Users\mat_i\AppData\Local\Programs\Python\Python313\Lib\site-packages\sqlalchemy\engine\default.py", line 621, in connect
    return self.loaded_dbapi.connect(*cargs, **cparams)
           │    │            │        │        └ {'host': '34.176.19.140', 'database': 'motoagency', 'user': 'matiasciafardini', 'port': 3306, 'charset': 'utf8mb4', 'buffered...
           │    │            │        └ ()
           │    │            └ <function connect at 0x000001B67B4B6E80>
           │    └ <module 'mysql.connector' from 'C:\\Users\\mat_i\\AppData\\Local\\Programs\\Python\\Python313\\Lib\\site-packages\\mysql\\con...
           └ <sqlalchemy.dialects.mysql.mysqlconnector.MySQLDialect_mysqlconnector object at 0x000001B67B494980>
  File "C:\Users\mat_i\AppData\Local\Programs\Python\Python313\Lib\site-packages\mysql\connector\pooling.py", line 322, in connect
    return CMySQLConnection(*args, **kwargs)
           │                 │       └ {'host': '34.176.19.140', 'database': 'motoagency', 'user': 'matiasciafardini', 'port': 3306, 'charset': 'utf8mb4', 'buffered...
           │                 └ ()
           └ <class 'mysql.connector.connection_cext.CMySQLConnection'>
  File "C:\Users\mat_i\AppData\Local\Programs\Python\Python313\Lib\site-packages\mysql\connector\connection_cext.py", line 142, in __init__
    self.connect(**kwargs)
    │    │         └ {'host': '34.176.19.140', 'database': 'motoagency', 'user': 'matiasciafardini', 'port': 3306, 'charset': 'utf8mb4', 'buffered...
    │    └ <function MySQLConnectionAbstract.connect at 0x000001B67A442FC0>
    └ <mysql.connector.connection_cext.CMySQLConnection object at 0x000001B67B497A10>
  File "C:\Users\mat_i\AppData\Local\Programs\Python\Python313\Lib\site-packages\mysql\connector\abstracts.py", line 1604, in connect
    self._open_connection()
    │    └ <function CMySQLConnection._open_connection at 0x000001B67B48B1A0>
    └ <mysql.connector.connection_cext.CMySQLConnection object at 0x000001B67B497A10>
  File "C:\Users\mat_i\AppData\Local\Programs\Python\Python313\Lib\site-packages\mysql\connector\connection_cext.py", line 360, in _open_connection
    raise get_mysql_exception(
          └ <function get_mysql_exception at 0x000001B67A3F8180>

sqlalchemy.exc.ProgrammingError: (mysql.connector.errors.ProgrammingError) 1045 (28000): Access denied for user 'matiasciafardini'@'188.81.239.217' (using password: NO)
(Background on this error at: https://sqlalche.me/e/20/f405)
